Workbook

Sheet 판정 기준
A1: MPS 멘탈 포지션 — 판정 기준
A3: 포지션 경계값 (3축, 1~6점) | B3: 4.5
A4: 강화할 멘탈 우선 선택 범위 (강점 기준까지 남은 점수) | B4: 0.3
A5: H 기준점 (가까움 계산용) | B5: 5.2
A6: L 기준점 (가까움 계산용) | B6: 3.8
A7: 가까움 점수 스케일 | B7: 5
A8: 5대 지표 강점 기준 (1~6점) | B8: 4.8
A9: ※ 노란 셀만 바꾸면 전체가 재계산됩니다. 포지션 분류는 3축(4.5 기준), "나의 강점·다음 3개월 강화할 멘탈"은 5대 지표(4.8 기준)로 판정합니다.
A11: 구분 | B11: 구성
A12: 3축: 압박 대처 (P) | B12: 경기긴장도 · 경기 안정성 · 경기 중 감정 조절 · 실패 후 회복력
A13: 3축: 준비 주도 (R) | B13: 경기 준비 능력 · 자기주도 학습능력 · 이미지트레이닝 활용능력
A14: 3축: 실수 회복 (I) | B14: 실수 후 회복력 · 외부평가 독립성
A15: 5대 지표 | B15: 경기긴장도 · 사회적 도움 활용 · 경기 준비 능력 · 실수 후 회복력 · 자기 통제력
A17: 포지션 가까움 (0~100) | B17: 가까움 = 100 × (1 − 3축 평균 거리 ÷ 스케일). 가장 가까운 포지션 = 대표 포지션. 8개 모두 표시해 한 포지션만 튀지 않게 함.
A18: 나의 강점 | B18: 5대 지표 중 강점 기준(4.8) 이상인 지표. 하나도 없으면 5대 지표 중 가장 높은 지표를 "가장 높은 지표"로 표시.
A19: 다음 3개월 강화할 멘탈 (1개) | B19: 강점 기준 미만 지표 중 ① 기준까지 0.3점 이내인 지표가 있으면 가장 가까운 지표 ② 없으면 실수 후 회복력 → 경기 준비 능력 → 경기긴장도 → 자기 통제력 → 사회적 도움 활용 순. 5개 모두 기준 이상이면 가장 낮은 지표를 "심화"로 표시.
A21: 알파벳 | B21: A~H는 이름표일 뿐 순서·우열이 없습니다. A~F는 강점 기준으로 원형 배치(준비 → 준비+압박 → 압박 → 압박+회복 → 회복 → 회복+준비), G·H는 3축 공통형.
A22: 닮은 선수 | B22: 공개된 경기 장면·인터뷰로 널리 알려진 모습을 바탕으로 한 "스타일 비유"이며, 해당 선수의 실제 심리 측정 결과가 아닙니다.
A23: 유의사항 | B23: 멘탈 포지션은 성격 판정이 아니라 측정 시점의 멘탈 사용 방식입니다. 3개월 재측정 시 이동할 수 있으며, 의료적 판단 목적이 아닙니다.

Sheet 리포트 카드
A1: 선수 선택 ▶ | B1: 이준후
A2: ※ 동명이인이 있으면 첫 번째 선수가 표시됩니다.
A4: 소속팀 | B4: =INDEX('선수별 포지션'!$C$2:$C$242,MATCH($B$1,'선수별 포지션'!$A$2:$A$242,0)) -> 서울세일중학교
A5: 측정일 | B5: =INDEX('선수별 포지션'!$D$2:$D$242,MATCH($B$1,'선수별 포지션'!$A$2:$A$242,0)) -> 46263
A6: 대표 포지션 | B6: =INDEX('선수별 포지션'!$W$2:$W$242,MATCH($B$1,'선수별 포지션'!$A$2:$A$242,0)) -> A
A7: 포지션명 | B7: =INDEX('선수별 포지션'!$X$2:$X$242,MATCH($B$1,'선수별 포지션'!$A$2:$A$242,0)) -> 섬세한 준비형
A8: 나의 강점 | B8: =INDEX('선수별 포지션'!$Y$2:$Y$242,MATCH($B$1,'선수별 포지션'!$A$2:$A$242,0)) -> 가장 높은 지표: 사회적 도움 활용
A9: 다음 3개월 강화할 멘탈 | B9: =INDEX('선수별 포지션'!$Z$2:$Z$242,MATCH($B$1,'선수별 포지션'!$A$2:$A$242,0)) -> 실수 후 회복력
A10: 닮은 선수 | B10: =INDEX('선수별 포지션'!$AA$2:$AA$242,MATCH($B$1,'선수별 포지션'!$A$2:$A$242,0)) -> 로베르트 레반도프스키 · 제임스 밀너 · 마르틴 외데고르
A11: [5대 지표] 경기긴장도 | B11: =INDEX('선수별 포지션'!$G$2:$G$242,MATCH($B$1,'선수별 포지션'!$A$2:$A$242,0)) -> 4.3
A12: [5대 지표] 사회적 도움 활용 | B12: =INDEX('선수별 포지션'!$Q$2:$Q$242,MATCH($B$1,'선수별 포지션'!$A$2:$A$242,0)) -> 4.6
A13: [5대 지표] 경기 준비 능력 | B13: =INDEX('선수별 포지션'!$K$2:$K$242,MATCH($B$1,'선수별 포지션'!$A$2:$A$242,0)) -> 4.6
A14: [5대 지표] 실수 후 회복력 | B14: =INDEX('선수별 포지션'!$N$2:$N$242,MATCH($B$1,'선수별 포지션'!$A$2:$A$242,0)) -> 4.6
A15: [5대 지표] 자기 통제력 | B15: =INDEX('선수별 포지션'!$P$2:$P$242,MATCH($B$1,'선수별 포지션'!$A$2:$A$242,0)) -> 4.3
A18: 포지션 가까움 (8개 전체, 높은 순)
A19: 순서 | B19: 알파벳 | C19: 포지션명 | D19: 가까움 (0~100)
A20: 1 | B20: =INDEX($H$20:$H$27,MATCH(LARGE($I$20:$I$27,1),$I$20:$I$27,0)) -> A | C20: =INDEX('포지션 정의'!$B$2:$B$9,MATCH(B20,'포지션 정의'!$A$2:$A$9,0)) -> 섬세한 준비형 | D20: =ROUND(LARGE($I$20:$I$27,1),0) -> 89 | H20: A | I20: =INDEX('선수별 포지션'!$AB$2:$AB$242,MATCH($B$1,'선수별 포지션'!$A$2:$A$242,0))-0/1000 -> 89
A21: 2 | B21: =INDEX($H$20:$H$27,MATCH(LARGE($I$20:$I$27,2),$I$20:$I$27,0)) -> F | C21: =INDEX('포지션 정의'!$B$2:$B$9,MATCH(B21,'포지션 정의'!$A$2:$A$9,0)) -> 성실한 도전자형 | D21: =ROUND(LARGE($I$20:$I$27,2),0) -> 88 | H21: B | I21: =INDEX('선수별 포지션'!$AC$2:$AC$242,MATCH($B$1,'선수별 포지션'!$A$2:$A$242,0))-1/1000 -> 83.999
A22: 3 | B22: =INDEX($H$20:$H$27,MATCH(LARGE($I$20:$I$27,3),$I$20:$I$27,0)) -> G | C22: =INDEX('포지션 정의'!$B$2:$B$9,MATCH(B22,'포지션 정의'!$A$2:$A$9,0)) -> 스펀지 흡수형 | D22: =ROUND(LARGE($I$20:$I$27,3),0) -> 88 | H22: C | I22: =INDEX('선수별 포지션'!$AD$2:$AD$242,MATCH($B$1,'선수별 포지션'!$A$2:$A$242,0))-2/1000 -> 82.998
A23: 4 | B23: =INDEX($H$20:$H$27,MATCH(LARGE($I$20:$I$27,4),$I$20:$I$27,0)) -> E | C23: =INDEX('포지션 정의'!$B$2:$B$9,MATCH(B23,'포지션 정의'!$A$2:$A$9,0)) -> 오뚝이 회복형 | D23: =ROUND(LARGE($I$20:$I$27,4),0) -> 87 | H23: D | I23: =INDEX('선수별 포지션'!$AE$2:$AE$242,MATCH($B$1,'선수별 포지션'!$A$2:$A$242,0))-3/1000 -> 81.997
A24: 5 | B24: =INDEX($H$20:$H$27,MATCH(LARGE($I$20:$I$27,5),$I$20:$I$27,0)) -> B | C24: =INDEX('포지션 정의'!$B$2:$B$9,MATCH(B24,'포지션 정의'!$A$2:$A$9,0)) -> 책임감 설계자형 | D24: =ROUND(LARGE($I$20:$I$27,5),0) -> 84 | H24: E | I24: =INDEX('선수별 포지션'!$AF$2:$AF$242,MATCH($B$1,'선수별 포지션'!$A$2:$A$242,0))-4/1000 -> 86.996
A25: 6 | B25: =INDEX($H$20:$H$27,MATCH(LARGE($I$20:$I$27,6),$I$20:$I$27,0)) -> C | C25: =INDEX('포지션 정의'!$B$2:$B$9,MATCH(B25,'포지션 정의'!$A$2:$A$9,0)) -> 침착한 감각형 | D25: =ROUND(LARGE($I$20:$I$27,6),0) -> 83 | H25: F | I25: =INDEX('선수별 포지션'!$AG$2:$AG$242,MATCH($B$1,'선수별 포지션'!$A$2:$A$242,0))-5/1000 -> 87.995
A26: 7 | B26: =INDEX($H$20:$H$27,MATCH(LARGE($I$20:$I$27,7),$I$20:$I$27,0)) -> H | C26: =INDEX('포지션 정의'!$B$2:$B$9,MATCH(B26,'포지션 정의'!$A$2:$A$9,0)) -> 올라운드 밸런스형 | D26: =ROUND(LARGE($I$20:$I$27,7),0) -> 83 | H26: G | I26: =INDEX('선수별 포지션'!$AH$2:$AH$242,MATCH($B$1,'선수별 포지션'!$A$2:$A$242,0))-6/1000 -> 87.994
A27: 8 | B27: =INDEX($H$20:$H$27,MATCH(LARGE($I$20:$I$27,8),$I$20:$I$27,0)) -> D | C27: =INDEX('포지션 정의'!$B$2:$B$9,MATCH(B27,'포지션 정의'!$A$2:$A$9,0)) -> 실전 승부사형 | D27: =ROUND(LARGE($I$20:$I$27,8),0) -> 82 | H27: H | I27: =INDEX('선수별 포지션'!$AI$2:$AI$242,MATCH($B$1,'선수별 포지션'!$A$2:$A$242,0))-7/1000 -> 82.993

Sheet 포지션 정의
A1: 알파벳 | B1: 포지션명 | C1: 영문명 | D1: 코드 (P-R-I) | E1: 강점 축 | F1: 인원 | G1: 비율 | H1: 한 줄 설명 | I1: 장점 | J1: 성장 포인트 | K1: 코칭 포인트 | L1: 닮은 해외 선수 (스타일 비유) | M1: 선수 비유 이유 | N1: 기준점 P | O1: 기준점 R | P1: 기준점 I
A2: A | B2: 섬세한 준비형 | C2: Detail Preparer | D2: LHL | E2: 준비 주도 | F2: =COUNTIF('선수별 포지션'!$W$2:$W$242,A2) -> 35 | G2: =F2/SUM($F$2:$F$9) -> 0.14522822 | H2: 누구보다 꼼꼼히 준비하고, 코칭을 빠르게 흡수하는 포지션. | I2: · 계획·분석·이미지트레이닝 활용이 뛰어남 · 코칭 수용도가 높아 연습에서 개선 속도가 빠름 · 훈련 태도가 성실함 | J2: · 연습에서 보여준 기량을 경기에서 그대로 꺼내는 힘 · 실수 한 번이 다음 플레이로 이어지지 않게 끊는 힘 | K2: · 실수했을 때 할 행동까지 준비 계획에 넣기 · 경기 결과와 "나"를 분리해 이야기하기 · 작은 성공 경기 경험 설계 | L2: 로베르트 레반도프스키 · 제임스 밀너 · 마르틴 외데고르 | M2: 식단·수면·훈련 루틴을 철저히 관리하는 준비의 대명사(레반도프스키), 30대 후반까지 이어진 자기관리(밀너), 어린 나이 기대와 시행착오를 꾸준한 준비로 이겨낸 성장(외데고르) | N2: =IF(MID($D2,1,1)="H",'판정 기준'!$B$5,'판정 기준'!$B$6) -> 3.8 | O2: =IF(MID($D2,2,1)="H",'판정 기준'!$B$5,'판정 기준'!$B$6) -> 5.2 | P2: =IF(MID($D2,3,1)="H",'판정 기준'!$B$5,'판정 기준'!$B$6) -> 3.8
A3: B | B3: 책임감 설계자형 | C3: Responsible Planner | D3: HHL | E3: 준비 주도 · 압박 대처 | F3: =COUNTIF('선수별 포지션'!$W$2:$W$242,A3) -> 13 | G3: =F3/SUM($F$2:$F$9) -> 0.053941909 | H3: 경기 중 침착하고 준비도 철저한, 책임감으로 팀을 받치는 포지션. | I3: · 준비 주도가 8포지션 중 가장 높은 편 · 경기 중 감정이 안정적 · 훈련 태도가 가장 성실한 그룹 | J3: · 실수 후 주변 평가에 덜 흔들리는 힘 · 완벽하지 않아도 괜찮다는 여유 | K3: · 결과보다 과정(준비·시도)을 먼저 칭찬하기 · 1~2초 "실수 리셋" 신호 동작 만들기 · 스스로 잘한 점부터 말하게 하기 | L3: 해리 케인 · 토니 크로스 · 필립 람 | M3: 킥 루틴과 몸 관리를 치밀하게 설계하는 스타일(케인), 큰 경기에서도 흔들림 없는 차분한 경기 운영(크로스), 분석적이고 원칙을 지키는 주장(람) | N3: =IF(MID($D3,1,1)="H",'판정 기준'!$B$5,'판정 기준'!$B$6) -> 5.2 | O3: =IF(MID($D3,2,1)="H",'판정 기준'!$B$5,'판정 기준'!$B$6) -> 5.2 | P3: =IF(MID($D3,3,1)="H",'판정 기준'!$B$5,'판정 기준'!$B$6) -> 3.8
A4: C | B4: 침착한 감각형 | C4: Calm Instinct | D4: HLL | E4: 압박 대처 | F4: =COUNTIF('선수별 포지션'!$W$2:$W$242,A4) -> 6 | G4: =F4/SUM($F$2:$F$9) -> 0.024896266 | H4: 긴장되는 순간에도 겉으로 흔들리지 않는, 차분함이 무기인 포지션. | I4: · 압박 상황에서 크게 무너지지 않는 침착함 · 주변의 도움과 조언을 잘 받아들임 | J4: · 나만의 준비 루틴 만들기 · 실수를 속으로 쌓아두지 않고 털어내기 · 훈련 동기 꾸준히 유지하기 | K4: · 침착함을 강점으로 먼저 인정하기 · 작은 목표를 자주 달성하게 하기 · 표현하지 않는 감정을 꺼내는 1:1 대화 | L4: 안드레아 피를로 · 디미타르 베르바토프 · 메수트 외질 | M4: 결승 무대에서도 여유로운 패스와 파넨카킥(피를로), 서두르지 않는 볼 터치와 여유(베르바토프), 감각적인 시야와 차분한 플레이메이킹(외질) | N4: =IF(MID($D4,1,1)="H",'판정 기준'!$B$5,'판정 기준'!$B$6) -> 5.2 | O4: =IF(MID($D4,2,1)="H",'판정 기준'!$B$5,'판정 기준'!$B$6) -> 3.8 | P4: =IF(MID($D4,3,1)="H",'판정 기준'!$B$5,'판정 기준'!$B$6) -> 3.8
A5: D | B5: 실전 승부사형 | C5: Game-Day Competitor | D5: HLH | E5: 압박 대처 · 실수 회복 | F5: =COUNTIF('선수별 포지션'!$W$2:$W$242,A5) -> 29 | G5: =F5/SUM($F$2:$F$9) -> 0.12033195 | H5: 큰 무대일수록 강하고, 실수도 금방 털어내는 배짱의 포지션. | I5: · 승부처·실전 무대에 강함 · 남의 시선에 흔들리지 않는 배짱 · 팀 내 적응력과 분위기 메이킹 | J5: · 감각을 루틴으로 만드는 힘(경기 전 준비·경기 후 복기) · 컨디션에 따른 기복 줄이기 | K5: · 짧은 경기 전 루틴 1가지 정하기 · 경기 후 3줄 기록(좋았던 점·아쉬운 점·다음 목표) · 감각을 말로 설명해보게 하기 | L5: 즐라탄 이브라히모비치 · 호나우지뉴 · 디에고 마라도나 | M5: 어떤 무대에서도 자신감이 넘치는 존재감(즐라탄), 즐기면서 결정적 순간을 만드는 창의성(호나우지뉴), 월드컵이라는 최대 무대에서 빛난 승부 감각(마라도나) | N5: =IF(MID($D5,1,1)="H",'판정 기준'!$B$5,'판정 기준'!$B$6) -> 5.2 | O5: =IF(MID($D5,2,1)="H",'판정 기준'!$B$5,'판정 기준'!$B$6) -> 3.8 | P5: =IF(MID($D5,3,1)="H",'판정 기준'!$B$5,'판정 기준'!$B$6) -> 5.2
A6: E | B6: 오뚝이 회복형 | C6: Bounce-Back | D6: LLH | E6: 실수 회복 | F6: =COUNTIF('선수별 포지션'!$W$2:$W$242,A6) -> 23 | G6: =F6/SUM($F$2:$F$9) -> 0.095435685 | H6: 넘어져도 금방 다시 일어나는, 회복력과 긍정이 무기인 포지션. | I6: · 실패를 오래 끌지 않는 회복력 · 주변 시선에 덜 위축됨 · 도전 자체를 즐기는 긍정성 | J6: · 긴장을 준비로 바꾸는 힘 · "괜찮아"로 넘기지 않고 원인도 함께 돌아보기 · 컨디션 관리 습관 | K6: · 회복력을 칭찬하되 "왜 긴장했는지" 함께 돌아보기 · 경기 전 준비 체크리스트 1장 · 수면·컨디션 루틴 연계 | L6: 올리비에 지루 · 디에고 포를란 · 라다멜 팔카오 | M6: 많은 비판 속에서도 묵묵히 월드컵 우승까지 간 꾸준함(지루), 잉글랜드에서 고전한 뒤 월드컵 골든볼로 재도약(포를란), 긴 부상 공백 후 다시 돌아온 복귀 스토리(팔카오) | N6: =IF(MID($D6,1,1)="H",'판정 기준'!$B$5,'판정 기준'!$B$6) -> 3.8 | O6: =IF(MID($D6,2,1)="H",'판정 기준'!$B$5,'판정 기준'!$B$6) -> 3.8 | P6: =IF(MID($D6,3,1)="H",'판정 기준'!$B$5,'판정 기준'!$B$6) -> 5.2
A7: F | B7: 성실한 도전자형 | C7: Steady Challenger | D7: LHH | E7: 준비 주도 · 실수 회복 | F7: =COUNTIF('선수별 포지션'!$W$2:$W$242,A7) -> 18 | G7: =F7/SUM($F$2:$F$9) -> 0.074688797 | H7: 긴장이 찾아와도, 준비와 노력으로 스스로 이겨내는 포지션. | I7: · "노력으로 극복하는" 준비력 · 남의 평가보다 자기 기준을 중시 · 좌절 후 다시 일어나는 힘 | J7: · 중요한 경기에서 연습만큼 발휘하는 힘 · 긴장이 몸의 굳음으로 이어지지 않게 하기 | K7: · 긴장을 "준비됐다는 신호"로 바꿔 말하기 · 연습 중 압박 상황 시뮬레이션 · 경기 직전 짧은 호흡 루틴(참고 수준) | L7: 제이미 바디 · 은골로 캉테 · 박지성 | M7: 하부리그에서 노력으로 프리미어리그 우승까지 오른 스토리(바디), 누구보다 많이 뛰는 성실함과 겸손(캉테), 끊임없는 노력으로 유럽 빅클럽에서 인정받은 성장(박지성) | N7: =IF(MID($D7,1,1)="H",'판정 기준'!$B$5,'판정 기준'!$B$6) -> 3.8 | O7: =IF(MID($D7,2,1)="H",'판정 기준'!$B$5,'판정 기준'!$B$6) -> 5.2 | P7: =IF(MID($D7,3,1)="H",'판정 기준'!$B$5,'판정 기준'!$B$6) -> 5.2
A8: G | B8: 스펀지 흡수형 | C8: Sponge | D8: LLL | E8: 보조 강점(도움 수용·태도) | F8: =COUNTIF('선수별 포지션'!$W$2:$W$242,A8) -> 48 | G8: =F8/SUM($F$2:$F$9) -> 0.19917012 | H8: 코칭과 경험을 빠르게 흡수하며, 가장 큰 폭의 변화를 만들 수 있는 출발점 포지션. | I8: · 주변의 도움과 조언을 받아들일 준비가 되어 있음 · 3개월 단위 변화가 가장 뚜렷하게 보일 수 있음 · 아직 형성기라 어떤 방향으로든 성장 여지가 큼 | J8: · 한 번에 한 축씩: 실수 회복 → 준비 주도 → 압박 대처 · 작은 성공 경험으로 자신감 쌓기 | K8: · 목표는 한 번에 하나만 · 결과보다 시도에 대한 피드백 · 보호자·지도자와 같은 메시지 공유 | L8: 디디에 드로그바 · 앙투안 그리즈만 · 모하메드 살라 | M8: 늦은 나이에 프로에 데뷔해 경험을 흡수하며 세계적 공격수로 성장(드로그바), 작은 체격으로 여러 유스팀에서 탈락한 뒤 크게 성장(그리즈만), 첫 빅클럽 도전 후 경험을 쌓아 정상급으로 재도약(살라) | N8: =IF(MID($D8,1,1)="H",'판정 기준'!$B$5,'판정 기준'!$B$6) -> 3.8 | O8: =IF(MID($D8,2,1)="H",'판정 기준'!$B$5,'판정 기준'!$B$6) -> 3.8 | P8: =IF(MID($D8,3,1)="H",'판정 기준'!$B$5,'판정 기준'!$B$6) -> 3.8
A9: H | B9: 올라운드 밸런스형 | C9: All-Round Balancer | D9: HHH | E9: 압박 대처 · 준비 주도 · 실수 회복 | F9: =COUNTIF('선수별 포지션'!$W$2:$W$242,A9) -> 69 | G9: =F9/SUM($F$2:$F$9) -> 0.28630705 | H9: 압박·준비·회복 3축이 고르게 받쳐주는, 균형이 무기인 포지션. | I9: · 큰 경기에서 평소 기량 발휘 · 스스로 목표와 루틴을 세움 · 팀 분위기를 잡아주는 중심 역할 | J9: · 이미 고른 3축 위에 "심화 목표" 세우기 · 첫 큰 좌절(정체·부상) 대비 · 커지는 기대에 대한 부담 관리 | K9: · 더 높은 수준의 도전 과제 · 주장·후배 멘토 등 리더 역할 · 좌절 상황을 미리 이야기해보기 | L9: 크리스티아누 호날두 · 루카 모드리치 · 버질 반 다이크 | M9: 철저한 자기관리와 결정적 순간의 존재감(호날두), 30대 후반까지 이어진 꾸준함과 리더십(모드리치), 어떤 공격수 앞에서도 침착한 수비 리더(반 다이크) | N9: =IF(MID($D9,1,1)="H",'판정 기준'!$B$5,'판정 기준'!$B$6) -> 5.2 | O9: =IF(MID($D9,2,1)="H",'판정 기준'!$B$5,'판정 기준'!$B$6) -> 5.2 | P9: =IF(MID($D9,3,1)="H",'판정 기준'!$B$5,'판정 기준'!$B$6) -> 5.2
E10: 합계 | F10: =SUM(F2:F9) -> 241

Sheet 포지션별 프로필
A1: 알파벳 | B1: 포지션명 | C1: 인원 | D1: MGI | E1: 압박 대처 P | F1: 준비 주도 R | G1: 실수 회복 I | H1: 경기긴장도 | I1: 경기 안정성 | J1: 경기 중 감정 조절 | K1: 실패 후 회복력 | L1: 경기 준비 능력 | M1: 자기주도 학습능력 | N1: 이미지트레이닝 활용능력 | O1: 실수 후 회복력 | P1: 외부평가 독립성 | Q1: 자기 통제력 | R1: 사회적 도움 활용 | S1: 훈련 태도 지수
A2: A | B2: 섬세한 준비형 | C2: =COUNTIF('선수별 포지션'!$W$2:$W$242,A2) -> 35 | D2: =IFERROR(AVERAGEIFS('선수별 포지션'!$F$2:$F$242,'선수별 포지션'!$W$2:$W$242,$A2),"-") -> 4.0114286 | E2: =IFERROR(AVERAGEIFS('선수별 포지션'!$S$2:$S$242,'선수별 포지션'!$W$2:$W$242,$A2),"-") -> 3.6671429 | F2: =IFERROR(AVERAGEIFS('선수별 포지션'!$T$2:$T$242,'선수별 포지션'!$W$2:$W$242,$A2),"-") -> 4.9580952 | G2: =IFERROR(AVERAGEIFS('선수별 포지션'!$U$2:$U$242,'선수별 포지션'!$W$2:$W$242,$A2),"-") -> 3.5971429 | H2: =IFERROR(AVERAGEIFS('선수별 포지션'!$G$2:$G$242,'선수별 포지션'!$W$2:$W$242,$A2),"-") -> 3.6057143 | I2: =IFERROR(AVERAGEIFS('선수별 포지션'!$H$2:$H$242,'선수별 포지션'!$W$2:$W$242,$A2),"-") -> 3.4885714 | J2: =IFERROR(AVERAGEIFS('선수별 포지션'!$I$2:$I$242,'선수별 포지션'!$W$2:$W$242,$A2),"-") -> 4.1542857 | K2: =IFERROR(AVERAGEIFS('선수별 포지션'!$J$2:$J$242,'선수별 포지션'!$W$2:$W$242,$A2),"-") -> 3.42 | L2: =IFERROR(AVERAGEIFS('선수별 포지션'!$K$2:$K$242,'선수별 포지션'!$W$2:$W$242,$A2),"-") -> 4.96 | M2: =IFERROR(AVERAGEIFS('선수별 포지션'!$L$2:$L$242,'선수별 포지션'!$W$2:$W$242,$A2),"-") -> 4.8657143 | N2: =IFERROR(AVERAGEIFS('선수별 포지션'!$M$2:$M$242,'선수별 포지션'!$W$2:$W$242,$A2),"-") -> 5.0485714 | O2: =IFERROR(AVERAGEIFS('선수별 포지션'!$N$2:$N$242,'선수별 포지션'!$W$2:$W$242,$A2),"-") -> 3.5342857 | P2: =IFERROR(AVERAGEIFS('선수별 포지션'!$O$2:$O$242,'선수별 포지션'!$W$2:$W$242,$A2),"-") -> 3.66 | Q2: =IFERROR(AVERAGEIFS('선수별 포지션'!$P$2:$P$242,'선수별 포지션'!$W$2:$W$242,$A2),"-") -> 4.0657143 | R2: =IFERROR(AVERAGEIFS('선수별 포지션'!$Q$2:$Q$242,'선수별 포지션'!$W$2:$W$242,$A2),"-") -> 4.7371429 | S2: =IFERROR(AVERAGEIFS('선수별 포지션'!$R$2:$R$242,'선수별 포지션'!$W$2:$W$242,$A2),"-") -> 5.3028571
A3: B | B3: 책임감 설계자형 | C3: =COUNTIF('선수별 포지션'!$W$2:$W$242,A3) -> 13 | D3: =IFERROR(AVERAGEIFS('선수별 포지션'!$F$2:$F$242,'선수별 포지션'!$W$2:$W$242,$A3),"-") -> 4.7538462 | E3: =IFERROR(AVERAGEIFS('선수별 포지션'!$S$2:$S$242,'선수별 포지션'!$W$2:$W$242,$A3),"-") -> 5.0403846 | F3: =IFERROR(AVERAGEIFS('선수별 포지션'!$T$2:$T$242,'선수별 포지션'!$W$2:$W$242,$A3),"-") -> 5.1666667 | G3: =IFERROR(AVERAGEIFS('선수별 포지션'!$U$2:$U$242,'선수별 포지션'!$W$2:$W$242,$A3),"-") -> 3.9038462 | H3: =IFERROR(AVERAGEIFS('선수별 포지션'!$G$2:$G$242,'선수별 포지션'!$W$2:$W$242,$A3),"-") -> 5.0076923 | I3: =IFERROR(AVERAGEIFS('선수별 포지션'!$H$2:$H$242,'선수별 포지션'!$W$2:$W$242,$A3),"-") -> 5.0153846 | J3: =IFERROR(AVERAGEIFS('선수별 포지션'!$I$2:$I$242,'선수별 포지션'!$W$2:$W$242,$A3),"-") -> 5.2461538 | K3: =IFERROR(AVERAGEIFS('선수별 포지션'!$J$2:$J$242,'선수별 포지션'!$W$2:$W$242,$A3),"-") -> 4.8923077 | L3: =IFERROR(AVERAGEIFS('선수별 포지션'!$K$2:$K$242,'선수별 포지션'!$W$2:$W$242,$A3),"-") -> 5.1615385 | M3: =IFERROR(AVERAGEIFS('선수별 포지션'!$L$2:$L$242,'선수별 포지션'!$W$2:$W$242,$A3),"-") -> 5.1692308 | N3: =IFERROR(AVERAGEIFS('선수별 포지션'!$M$2:$M$242,'선수별 포지션'!$W$2:$W$242,$A3),"-") -> 5.1692308 | O3: =IFERROR(AVERAGEIFS('선수별 포지션'!$N$2:$N$242,'선수별 포지션'!$W$2:$W$242,$A3),"-") -> 3.8153846 | P3: =IFERROR(AVERAGEIFS('선수별 포지션'!$O$2:$O$242,'선수별 포지션'!$W$2:$W$242,$A3),"-") -> 3.9923077 | Q3: =IFERROR(AVERAGEIFS('선수별 포지션'!$P$2:$P$242,'선수별 포지션'!$W$2:$W$242,$A3),"-") -> 4.7461538 | R3: =IFERROR(AVERAGEIFS('선수별 포지션'!$Q$2:$Q$242,'선수별 포지션'!$W$2:$W$242,$A3),"-") -> 5.4769231 | S3: =IFERROR(AVERAGEIFS('선수별 포지션'!$R$2:$R$242,'선수별 포지션'!$W$2:$W$242,$A3),"-") -> 5.8230769
A4: C | B4: 침착한 감각형 | C4: =COUNTIF('선수별 포지션'!$W$2:$W$242,A4) -> 6 | D4: =IFERROR(AVERAGEIFS('선수별 포지션'!$F$2:$F$242,'선수별 포지션'!$W$2:$W$242,$A4),"-") -> 4.1666667 | E4: =IFERROR(AVERAGEIFS('선수별 포지션'!$S$2:$S$242,'선수별 포지션'!$W$2:$W$242,$A4),"-") -> 4.7958333 | F4: =IFERROR(AVERAGEIFS('선수별 포지션'!$T$2:$T$242,'선수별 포지션'!$W$2:$W$242,$A4),"-") -> 3.8833333 | G4: =IFERROR(AVERAGEIFS('선수별 포지션'!$U$2:$U$242,'선수별 포지션'!$W$2:$W$242,$A4),"-") -> 4.0166667 | H4: =IFERROR(AVERAGEIFS('선수별 포지션'!$G$2:$G$242,'선수별 포지션'!$W$2:$W$242,$A4),"-") -> 4.8666667 | I4: =IFERROR(AVERAGEIFS('선수별 포지션'!$H$2:$H$242,'선수별 포지션'!$W$2:$W$242,$A4),"-") -> 4.5333333 | J4: =IFERROR(AVERAGEIFS('선수별 포지션'!$I$2:$I$242,'선수별 포지션'!$W$2:$W$242,$A4),"-") -> 5.3333333 | K4: =IFERROR(AVERAGEIFS('선수별 포지션'!$J$2:$J$242,'선수별 포지션'!$W$2:$W$242,$A4),"-") -> 4.45 | L4: =IFERROR(AVERAGEIFS('선수별 포지션'!$K$2:$K$242,'선수별 포지션'!$W$2:$W$242,$A4),"-") -> 3.8833333 | M4: =IFERROR(AVERAGEIFS('선수별 포지션'!$L$2:$L$242,'선수별 포지션'!$W$2:$W$242,$A4),"-") -> 3.8833333 | N4: =IFERROR(AVERAGEIFS('선수별 포지션'!$M$2:$M$242,'선수별 포지션'!$W$2:$W$242,$A4),"-") -> 3.8833333 | O4: =IFERROR(AVERAGEIFS('선수별 포지션'!$N$2:$N$242,'선수별 포지션'!$W$2:$W$242,$A4),"-") -> 3.8666667 | P4: =IFERROR(AVERAGEIFS('선수별 포지션'!$O$2:$O$242,'선수별 포지션'!$W$2:$W$242,$A4),"-") -> 4.1666667 | Q4: =IFERROR(AVERAGEIFS('선수별 포지션'!$P$2:$P$242,'선수별 포지션'!$W$2:$W$242,$A4),"-") -> 4.0333333 | R4: =IFERROR(AVERAGEIFS('선수별 포지션'!$Q$2:$Q$242,'선수별 포지션'!$W$2:$W$242,$A4),"-") -> 5.3666667 | S4: =IFERROR(AVERAGEIFS('선수별 포지션'!$R$2:$R$242,'선수별 포지션'!$W$2:$W$242,$A4),"-") -> 4.7833333
A5: D | B5: 실전 승부사형 | C5: =COUNTIF('선수별 포지션'!$W$2:$W$242,A5) -> 29 | D5: =IFERROR(AVERAGEIFS('선수별 포지션'!$F$2:$F$242,'선수별 포지션'!$W$2:$W$242,$A5),"-") -> 4.7931034 | E5: =IFERROR(AVERAGEIFS('선수별 포지션'!$S$2:$S$242,'선수별 포지션'!$W$2:$W$242,$A5),"-") -> 5.087931 | F5: =IFERROR(AVERAGEIFS('선수별 포지션'!$T$2:$T$242,'선수별 포지션'!$W$2:$W$242,$A5),"-") -> 3.9310345 | G5: =IFERROR(AVERAGEIFS('선수별 포지션'!$U$2:$U$242,'선수별 포지션'!$W$2:$W$242,$A5),"-") -> 5.4551724 | H5: =IFERROR(AVERAGEIFS('선수별 포지션'!$G$2:$G$242,'선수별 포지션'!$W$2:$W$242,$A5),"-") -> 5.0413793 | I5: =IFERROR(AVERAGEIFS('선수별 포지션'!$H$2:$H$242,'선수별 포지션'!$W$2:$W$242,$A5),"-") -> 5.0103448 | J5: =IFERROR(AVERAGEIFS('선수별 포지션'!$I$2:$I$242,'선수별 포지션'!$W$2:$W$242,$A5),"-") -> 5.4413793 | K5: =IFERROR(AVERAGEIFS('선수별 포지션'!$J$2:$J$242,'선수별 포지션'!$W$2:$W$242,$A5),"-") -> 4.8586207 | L5: =IFERROR(AVERAGEIFS('선수별 포지션'!$K$2:$K$242,'선수별 포지션'!$W$2:$W$242,$A5),"-") -> 3.9310345 | M5: =IFERROR(AVERAGEIFS('선수별 포지션'!$L$2:$L$242,'선수별 포지션'!$W$2:$W$242,$A5),"-") -> 3.9793103 | N5: =IFERROR(AVERAGEIFS('선수별 포지션'!$M$2:$M$242,'선수별 포지션'!$W$2:$W$242,$A5),"-") -> 3.8827586 | O5: =IFERROR(AVERAGEIFS('선수별 포지션'!$N$2:$N$242,'선수별 포지션'!$W$2:$W$242,$A5),"-") -> 5.4517241 | P5: =IFERROR(AVERAGEIFS('선수별 포지션'!$O$2:$O$242,'선수별 포지션'!$W$2:$W$242,$A5),"-") -> 5.4586207 | Q5: =IFERROR(AVERAGEIFS('선수별 포지션'!$P$2:$P$242,'선수별 포지션'!$W$2:$W$242,$A5),"-") -> 4.5551724 | R5: =IFERROR(AVERAGEIFS('선수별 포지션'!$Q$2:$Q$242,'선수별 포지션'!$W$2:$W$242,$A5),"-") -> 5.5448276 | S5: =IFERROR(AVERAGEIFS('선수별 포지션'!$R$2:$R$242,'선수별 포지션'!$W$2:$W$242,$A5),"-") -> 5.4758621
A6: E | B6: 오뚝이 회복형 | C6: =COUNTIF('선수별 포지션'!$W$2:$W$242,A6) -> 23 | D6: =IFERROR(AVERAGEIFS('선수별 포지션'!$F$2:$F$242,'선수별 포지션'!$W$2:$W$242,$A6),"-") -> 4.3217391 | E6: =IFERROR(AVERAGEIFS('선수별 포지션'!$S$2:$S$242,'선수별 포지션'!$W$2:$W$242,$A6),"-") -> 4.0304348 | F6: =IFERROR(AVERAGEIFS('선수별 포지션'!$T$2:$T$242,'선수별 포지션'!$W$2:$W$242,$A6),"-") -> 3.8434783 | G6: =IFERROR(AVERAGEIFS('선수별 포지션'!$U$2:$U$242,'선수별 포지션'!$W$2:$W$242,$A6),"-") -> 5.0521739 | H6: =IFERROR(AVERAGEIFS('선수별 포지션'!$G$2:$G$242,'선수별 포지션'!$W$2:$W$242,$A6),"-") -> 4.073913 | I6: =IFERROR(AVERAGEIFS('선수별 포지션'!$H$2:$H$242,'선수별 포지션'!$W$2:$W$242,$A6),"-") -> 3.8565217 | J6: =IFERROR(AVERAGEIFS('선수별 포지션'!$I$2:$I$242,'선수별 포지션'!$W$2:$W$242,$A6),"-") -> 4.3826087 | K6: =IFERROR(AVERAGEIFS('선수별 포지션'!$J$2:$J$242,'선수별 포지션'!$W$2:$W$242,$A6),"-") -> 3.8086957 | L6: =IFERROR(AVERAGEIFS('선수별 포지션'!$K$2:$K$242,'선수별 포지션'!$W$2:$W$242,$A6),"-") -> 3.8521739 | M6: =IFERROR(AVERAGEIFS('선수별 포지션'!$L$2:$L$242,'선수별 포지션'!$W$2:$W$242,$A6),"-") -> 3.7434783 | N6: =IFERROR(AVERAGEIFS('선수별 포지션'!$M$2:$M$242,'선수별 포지션'!$W$2:$W$242,$A6),"-") -> 3.9347826 | O6: =IFERROR(AVERAGEIFS('선수별 포지션'!$N$2:$N$242,'선수별 포지션'!$W$2:$W$242,$A6),"-") -> 5.0608696 | P6: =IFERROR(AVERAGEIFS('선수별 포지션'!$O$2:$O$242,'선수별 포지션'!$W$2:$W$242,$A6),"-") -> 5.0434783 | Q6: =IFERROR(AVERAGEIFS('선수별 포지션'!$P$2:$P$242,'선수별 포지션'!$W$2:$W$242,$A6),"-") -> 4.1130435 | R6: =IFERROR(AVERAGEIFS('선수별 포지션'!$Q$2:$Q$242,'선수별 포지션'!$W$2:$W$242,$A6),"-") -> 4.8521739 | S6: =IFERROR(AVERAGEIFS('선수별 포지션'!$R$2:$R$242,'선수별 포지션'!$W$2:$W$242,$A6),"-") -> 5.3478261
A7: F | B7: 성실한 도전자형 | C7: =COUNTIF('선수별 포지션'!$W$2:$W$242,A7) -> 18 | D7: =IFERROR(AVERAGEIFS('선수별 포지션'!$F$2:$F$242,'선수별 포지션'!$W$2:$W$242,$A7),"-") -> 4.6444444 | E7: =IFERROR(AVERAGEIFS('선수별 포지션'!$S$2:$S$242,'선수별 포지션'!$W$2:$W$242,$A7),"-") -> 4.0097222 | F7: =IFERROR(AVERAGEIFS('선수별 포지션'!$T$2:$T$242,'선수별 포지션'!$W$2:$W$242,$A7),"-") -> 4.9203704 | G7: =IFERROR(AVERAGEIFS('선수별 포지션'!$U$2:$U$242,'선수별 포지션'!$W$2:$W$242,$A7),"-") -> 5.1527778 | H7: =IFERROR(AVERAGEIFS('선수별 포지션'!$G$2:$G$242,'선수별 포지션'!$W$2:$W$242,$A7),"-") -> 3.9833333 | I7: =IFERROR(AVERAGEIFS('선수별 포지션'!$H$2:$H$242,'선수별 포지션'!$W$2:$W$242,$A7),"-") -> 3.8944444 | J7: =IFERROR(AVERAGEIFS('선수별 포지션'!$I$2:$I$242,'선수별 포지션'!$W$2:$W$242,$A7),"-") -> 4.3777778 | K7: =IFERROR(AVERAGEIFS('선수별 포지션'!$J$2:$J$242,'선수별 포지션'!$W$2:$W$242,$A7),"-") -> 3.7833333 | L7: =IFERROR(AVERAGEIFS('선수별 포지션'!$K$2:$K$242,'선수별 포지션'!$W$2:$W$242,$A7),"-") -> 4.9111111 | M7: =IFERROR(AVERAGEIFS('선수별 포지션'!$L$2:$L$242,'선수별 포지션'!$W$2:$W$242,$A7),"-") -> 4.7444444 | N7: =IFERROR(AVERAGEIFS('선수별 포지션'!$M$2:$M$242,'선수별 포지션'!$W$2:$W$242,$A7),"-") -> 5.1055556 | O7: =IFERROR(AVERAGEIFS('선수별 포지션'!$N$2:$N$242,'선수별 포지션'!$W$2:$W$242,$A7),"-") -> 5.1 | P7: =IFERROR(AVERAGEIFS('선수별 포지션'!$O$2:$O$242,'선수별 포지션'!$W$2:$W$242,$A7),"-") -> 5.2055556 | Q7: =IFERROR(AVERAGEIFS('선수별 포지션'!$P$2:$P$242,'선수별 포지션'!$W$2:$W$242,$A7),"-") -> 4.4555556 | R7: =IFERROR(AVERAGEIFS('선수별 포지션'!$Q$2:$Q$242,'선수별 포지션'!$W$2:$W$242,$A7),"-") -> 4.9333333 | S7: =IFERROR(AVERAGEIFS('선수별 포지션'!$R$2:$R$242,'선수별 포지션'!$W$2:$W$242,$A7),"-") -> 5.4888889
A8: G | B8: 스펀지 흡수형 | C8: =COUNTIF('선수별 포지션'!$W$2:$W$242,A8) -> 48 | D8: =IFERROR(AVERAGEIFS('선수별 포지션'!$F$2:$F$242,'선수별 포지션'!$W$2:$W$242,$A8),"-") -> 3.7395833 | E8: =IFERROR(AVERAGEIFS('선수별 포지션'!$S$2:$S$242,'선수별 포지션'!$W$2:$W$242,$A8),"-") -> 3.59375 | F8: =IFERROR(AVERAGEIFS('선수별 포지션'!$T$2:$T$242,'선수별 포지션'!$W$2:$W$242,$A8),"-") -> 3.9652778 | G8: =IFERROR(AVERAGEIFS('선수별 포지션'!$U$2:$U$242,'선수별 포지션'!$W$2:$W$242,$A8),"-") -> 3.496875 | H8: =IFERROR(AVERAGEIFS('선수별 포지션'!$G$2:$G$242,'선수별 포지션'!$W$2:$W$242,$A8),"-") -> 3.5875 | I8: =IFERROR(AVERAGEIFS('선수별 포지션'!$H$2:$H$242,'선수별 포지션'!$W$2:$W$242,$A8),"-") -> 3.5416667 | J8: =IFERROR(AVERAGEIFS('선수별 포지션'!$I$2:$I$242,'선수별 포지션'!$W$2:$W$242,$A8),"-") -> 3.8541667 | K8: =IFERROR(AVERAGEIFS('선수별 포지션'!$J$2:$J$242,'선수별 포지션'!$W$2:$W$242,$A8),"-") -> 3.3916667 | L8: =IFERROR(AVERAGEIFS('선수별 포지션'!$K$2:$K$242,'선수별 포지션'!$W$2:$W$242,$A8),"-") -> 3.9625 | M8: =IFERROR(AVERAGEIFS('선수별 포지션'!$L$2:$L$242,'선수별 포지션'!$W$2:$W$242,$A8),"-") -> 3.9041667 | N8: =IFERROR(AVERAGEIFS('선수별 포지션'!$M$2:$M$242,'선수별 포지션'!$W$2:$W$242,$A8),"-") -> 4.0291667 | O8: =IFERROR(AVERAGEIFS('선수별 포지션'!$N$2:$N$242,'선수별 포지션'!$W$2:$W$242,$A8),"-") -> 3.5145833 | P8: =IFERROR(AVERAGEIFS('선수별 포지션'!$O$2:$O$242,'선수별 포지션'!$W$2:$W$242,$A8),"-") -> 3.4791667 | Q8: =IFERROR(AVERAGEIFS('선수별 포지션'!$P$2:$P$242,'선수별 포지션'!$W$2:$W$242,$A8),"-") -> 3.9375 | R8: =IFERROR(AVERAGEIFS('선수별 포지션'!$Q$2:$Q$242,'선수별 포지션'!$W$2:$W$242,$A8),"-") -> 4.4729167 | S8: =IFERROR(AVERAGEIFS('선수별 포지션'!$R$2:$R$242,'선수별 포지션'!$W$2:$W$242,$A8),"-") -> 4.89375
A9: H | B9: 올라운드 밸런스형 | C9: =COUNTIF('선수별 포지션'!$W$2:$W$242,A9) -> 69 | D9: =IFERROR(AVERAGEIFS('선수별 포지션'!$F$2:$F$242,'선수별 포지션'!$W$2:$W$242,$A9),"-") -> 5.2144928 | E9: =IFERROR(AVERAGEIFS('선수별 포지션'!$S$2:$S$242,'선수별 포지션'!$W$2:$W$242,$A9),"-") -> 5.1373188 | F9: =IFERROR(AVERAGEIFS('선수별 포지션'!$T$2:$T$242,'선수별 포지션'!$W$2:$W$242,$A9),"-") -> 5.1521739 | G9: =IFERROR(AVERAGEIFS('선수별 포지션'!$U$2:$U$242,'선수별 포지션'!$W$2:$W$242,$A9),"-") -> 5.4536232 | H9: =IFERROR(AVERAGEIFS('선수별 포지션'!$G$2:$G$242,'선수별 포지션'!$W$2:$W$242,$A9),"-") -> 5.0898551 | I9: =IFERROR(AVERAGEIFS('선수별 포지션'!$H$2:$H$242,'선수별 포지션'!$W$2:$W$242,$A9),"-") -> 5.1318841 | J9: =IFERROR(AVERAGEIFS('선수별 포지션'!$I$2:$I$242,'선수별 포지션'!$W$2:$W$242,$A9),"-") -> 5.3797101 | K9: =IFERROR(AVERAGEIFS('선수별 포지션'!$J$2:$J$242,'선수별 포지션'!$W$2:$W$242,$A9),"-") -> 4.9478261 | L9: =IFERROR(AVERAGEIFS('선수별 포지션'!$K$2:$K$242,'선수별 포지션'!$W$2:$W$242,$A9),"-") -> 5.1550725 | M9: =IFERROR(AVERAGEIFS('선수별 포지션'!$L$2:$L$242,'선수별 포지션'!$W$2:$W$242,$A9),"-") -> 5.1057971 | N9: =IFERROR(AVERAGEIFS('선수별 포지션'!$M$2:$M$242,'선수별 포지션'!$W$2:$W$242,$A9),"-") -> 5.1956522 | O9: =IFERROR(AVERAGEIFS('선수별 포지션'!$N$2:$N$242,'선수별 포지션'!$W$2:$W$242,$A9),"-") -> 5.4521739 | P9: =IFERROR(AVERAGEIFS('선수별 포지션'!$O$2:$O$242,'선수별 포지션'!$W$2:$W$242,$A9),"-") -> 5.4550725 | Q9: =IFERROR(AVERAGEIFS('선수별 포지션'!$P$2:$P$242,'선수별 포지션'!$W$2:$W$242,$A9),"-") -> 5.1028986 | R9: =IFERROR(AVERAGEIFS('선수별 포지션'!$Q$2:$Q$242,'선수별 포지션'!$W$2:$W$242,$A9),"-") -> 5.5333333 | S9: =IFERROR(AVERAGEIFS('선수별 포지션'!$R$2:$R$242,'선수별 포지션'!$W$2:$W$242,$A9),"-") -> 5.7521739
B10: 전체 평균 | C10: =SUM(C2:C9) -> 241 | D10: =AVERAGE('선수별 포지션'!$F$2:$F$242) -> 4.5165975 | E10: =AVERAGE('선수별 포지션'!$S$2:$S$242) -> 4.4068465 | F10: =AVERAGE('선수별 포지션'!$T$2:$T$242) -> 4.5676349 | G10: =AVERAGE('선수별 포지션'!$U$2:$U$242) -> 4.6143154 | H10: =AVERAGE('선수별 포지션'!$G$2:$G$242) -> 4.379668 | I10: =AVERAGE('선수별 포지션'!$H$2:$H$242) -> 4.326556 | J10: =AVERAGE('선수별 포지션'!$I$2:$I$242) -> 4.726971 | K10: =AVERAGE('선수별 포지션'!$J$2:$J$242) -> 4.1941909 | L10: =AVERAGE('선수별 포지션'!$K$2:$K$242) -> 4.5680498 | M10: =AVERAGE('선수별 포지션'!$L$2:$L$242) -> 4.5120332 | N10: =AVERAGE('선수별 포지션'!$M$2:$M$242) -> 4.6228216 | O10: =AVERAGE('선수별 포지션'!$N$2:$N$242) -> 4.5962656 | P10: =AVERAGE('선수별 포지션'!$O$2:$O$242) -> 4.6323651 | Q10: =AVERAGE('선수별 포지션'!$P$2:$P$242) -> 4.4655602 | R10: =AVERAGE('선수별 포지션'!$Q$2:$Q$242) -> 5.0908714 | S10: =AVERAGE('선수별 포지션'!$R$2:$R$242) -> 5.4041494

Sheet 선수별 포지션
A1: 선수명 | B1: 성별 | C1: 소속팀 | D1: 측정일 | E1: PHV 단계 | F1: MGI | G1: 경기긴장도 | H1: 경기 안정성 | I1: 경기 중 감정 조절 | J1: 실패 후 회복력 | K1: 경기 준비 능력 | L1: 자기주도 학습능력 | M1: 이미지트레이닝 활용능력 | N1: 실수 후 회복력 | O1: 외부평가 독립성 | P1: 자기 통제력 | Q1: 사회적 도움 활용 | R1: 훈련 태도 지수 | S1: 압박 대처 P | T1: 준비 주도 R | U1: 실수 회복 I | V1: 코드 | W1: 대표 포지션 | X1: 포지션명 | Y1: 나의 강점 | Z1: 다음 3개월 강화할 멘탈 | AA1: 닮은 선수 | AB1: 가까움 A 섬세한 준비형 | AC1: 가까움 B 책임감 설계자형 | AD1: 가까움 C 침착한 감각형 | AE1: 가까움 D 실전 승부사형 | AF1: 가까움 E 오뚝이 회복형 | AG1: 가까움 F 성실한 도전자형 | AH1: 가까움 G 스펀지 흡수형 | AI1: 가까움 H 올라운드 밸런스형 | AJ1: (보조) 강점 문자열 | AK1: h긴장 | AL1: h사회 | AM1: h준비 | AN1: h실수 | AO1: h통제 | AP1: h최고
A2: 임영준 | B2: 남 | C2: 서울세일중학교 | D2: 46270 | E2: PHV 1 | F2: 5.7 | G2: 5.6 | H2: 5.8 | I2: 5.8 | J2: 5.5 | K2: 5.7 | L2: 5.5 | M2: 5.9 | N2: 5.9 | O2: 6 | P2: 5.7 | Q2: 5.6 | R2: 6 | S2: =AVERAGE(G2:J2) -> 5.675 | T2: =AVERAGE(K2:M2) -> 5.7 | U2: =AVERAGE(N2:O2) -> 5.95 | V2: =IF(S2>='판정 기준'!$B$3,"H","L")&IF(T2>='판정 기준'!$B$3,"H","L")&IF(U2>='판정 기준'!$B$3,"H","L") -> HHH | W2: =INDEX('포지션 정의'!$A$2:$A$9,MATCH(V2,'포지션 정의'!$D$2:$D$9,0)) -> H | X2: =INDEX('포지션 정의'!$B$2:$B$9,MATCH(V2,'포지션 정의'!$D$2:$D$9,0)) -> 올라운드 밸런스형 | Y2: =IF(AJ2="","가장 높은 지표: "&AP2,LEFT(AJ2,LEN(AJ2)-2)) -> 경기긴장도, 사회적 도움 활용, 경기 준비 능력, 실수 후 회복력, 자기 통제력 | Z2: =IF(MAX(AK2:AO2)=0,"심화: "&IF(N2=MIN(G2,Q2,K2,N2,P2),"실수 후 회복력",IF(K2=MIN(G2,Q2,K2,N2,P2),"경기 준비 능력",IF(G2=MIN(G2,Q2,K2,N2,P2),"경기긴장도",IF(P2=MIN(G2,Q2,K2,N2,P2),"자기 통제력","사회적 도움 활용")))),IF(MAX(AK2:AO2)>='판정 기준'!$B$8-'판정 기준'!$B$4,IF(AN2=MAX(AK2:AO2),"실수 후 회복력",IF(AM2=MAX(AK2:AO2),"경기 준비 능력",IF(AK2=MAX(AK2:AO2),"경기긴장도",IF(AO2=MAX(AK2:AO2),"자기 통제력","사회적 도움 활용")))),IF(AN2>0,"실수 후 회복력",IF(AM2>0,"경기 준비 능력",IF(AK2>0,"경기긴장도",IF(AO2>0,"자기 통제력","사회적 도움 활용")))))) -> 심화: 경기긴장도 | AA2: =INDEX('포지션 정의'!$L$2:$L$9,MATCH(V2,'포지션 정의'!$D$2:$D$9,0)) -> 크리스티아누 호날두 · 루카 모드리치 · 버질 반 다이크 | AB2: =ROUND(100*(1-SQRT(((S2-'포지션 정의'!$N$2)^2+(T2-'포지션 정의'!$O$2)^2+(U2-'포지션 정의'!$P$2)^2)/3)/'판정 기준'!$B$7),0) -> 67 | AC2: =ROUND(100*(1-SQRT(((S2-'포지션 정의'!$N$3)^2+(T2-'포지션 정의'!$O$3)^2+(U2-'포지션 정의'!$P$3)^2)/3)/'판정 기준'!$B$7),0) -> 74 | AD2: =ROUND(100*(1-SQRT(((S2-'포지션 정의'!$N$4)^2+(T2-'포지션 정의'!$O$4)^2+(U2-'포지션 정의'!$P$4)^2)/3)/'판정 기준'!$B$7),0) -> 66 | AE2: =ROUND(100*(1-SQRT(((S2-'포지션 정의'!$N$5)^2+(T2-'포지션 정의'!$O$5)^2+(U2-'포지션 정의'!$P$5)^2)/3)/'판정 기준'!$B$7),0) -> 76 | AF2: =ROUND(100*(1-SQRT(((S2-'포지션 정의'!$N$6)^2+(T2-'포지션 정의'!$O$6)^2+(U2-'포지션 정의'!$P$6)^2)/3)/'판정 기준'!$B$7),0) -> 68 | AG2: =ROUND(100*(1-SQRT(((S2-'포지션 정의'!$N$7)^2+(T2-'포지션 정의'!$O$7)^2+(U2-'포지션 정의'!$P$7)^2)/3)/'판정 기준'!$B$7),0) -> 76 | AH2: =ROUND(100*(1-SQRT(((S2-'포지션 정의'!$N$8)^2+(T2-'포지션 정의'!$O$8)^2+(U2-'포지션 정의'!$P$8)^2)/3)/'판정 기준'!$B$7),0) -> 60 | AI2: =ROUND(100*(1-SQRT(((S2-'포지션 정의'!$N$9)^2+(T2-'포지션 정의'!$O$9)^2+(U2-'포지션 정의'!$P$9)^2)/3)/'판정 기준'!$B$7),0) -> 88 | AJ2: =IF(G2>='판정 기준'!$B$8,"경기긴장도, ","")&IF(Q2>='판정 기준'!$B$8,"사회적 도움 활용, ","")&IF(K2>='판정 기준'!$B$8,"경기 준비 능력, ","")&IF(N2>='판정 기준'!$B$8,"실수 후 회복력, ","")&IF(P2>='판정 기준'!$B$8,"자기 통제력, ","") -> 경기긴장도, 사회적 도움 활용, 경기 준비 능력, 실수 후 회복력, 자기 통제력, | AK2: =IF(AND(G2<'판정 기준'!$B$8,OR(AJ2<>"",AP2<>"경기긴장도")),G2,0) -> 0 | AL2: =IF(AND(Q2<'판정 기준'!$B$8,OR(AJ2<>"",AP2<>"사회적 도움 활용")),Q2,0) -> 0 | AM2: =IF(AND(K2<'판정 기준'!$B$8,OR(AJ2<>"",AP2<>"경기 준비 능력")),K2,0) -> 0 | AN2: =IF(AND(N2<'판정 기준'!$B$8,OR(AJ2<>"",AP2<>"실수 후 회복력")),N2,0) -> 0 | AO2: =IF(AND(P2<'판정 기준'!$B$8,OR(AJ2<>"",AP2<>"자기 통제력")),P2,0) -> 0 | AP2: =IF(Q2=MAX(G2,Q2,K2,N2,P2),"사회적 도움 활용",IF(P2=MAX(G2,Q2,K2,N2,P2),"자기 통제력",IF(G2=MAX(G2,Q2,K2,N2,P2),"경기긴장도",IF(K2=MAX(G2,Q2,K2,N2,P2),"경기 준비 능력","실수 후 회복력")))) -> 실수 후 회복력
A3: 백채아 | B3: 여 | C3: 서울서대문FC | D3: 46263 | E3: PHV 0 | F3: 4.8 | G3: 5.3 | H3: 5.2 | I3: 5.8 | J3: 4.7 | K3: 4 | L3: 3.7 | M3: 4.3 | N3: 5.9 | O3: 5.5 | P3: 3.5 | Q3: 5.4 | R3: 5.7 | S3: =AVERAGE(G3:J3) -> 5.25 | T3: =AVERAGE(K3:M3) -> 4 | U3: =AVERAGE(N3:O3) -> 5.7 | V3: =IF(S3>='판정 기준'!$B$3,"H","L")&IF(T3>='판정 기준'!$B$3,"H","L")&IF(U3>='판정 기준'!$B$3,"H","L") -> HLH | W3: =INDEX('포지션 정의'!$A$2:$A$9,MATCH(V3,'포지션 정의'!$D$2:$D$9,0)) -> D | X3: =INDEX('포지션 정의'!$B$2:$B$9,MATCH(V3,'포지션 정의'!$D$2:$D$9,0)) -> 실전 승부사형 | Y3: =IF(AJ3="","가장 높은 지표: "&AP3,LEFT(AJ3,LEN(AJ3)-2)) -> 경기긴장도, 사회적 도움 활용, 실수 후 회복력 | Z3: =IF(MAX(AK3:AO3)=0,"심화: "&IF(N3=MIN(G3,Q3,K3,N3,P3),"실수 후 회복력",IF(K3=MIN(G3,Q3,K3,N3,P3),"경기 준비 능력",IF(G3=MIN(G3,Q3,K3,N3,P3),"경기긴장도",IF(P3=MIN(G3,Q3,K3,N3,P3),"자기 통제력","사회적 도움 활용")))),IF(MAX(AK3:AO3)>='판정 기준'!$B$8-'판정 기준'!$B$4,IF(AN3=MAX(AK3:AO3),"실수 후 회복력",IF(AM3=MAX(AK3:AO3),"경기 준비 능력",IF(AK3=MAX(AK3:AO3),"경기긴장도",IF(AO3=MAX(AK3:AO3),"자기 통제력","사회적 도움 활용")))),IF(AN3>0,"실수 후 회복력",IF(AM3>0,"경기 준비 능력",IF(AK3>0,"경기긴장도",IF(AO3>0,"자기 통제력","사회적 도움 활용")))))) -> 경기 준비 능력 | AA3: =INDEX('포지션 정의'!$L$2:$L$9,MATCH(V3,'포지션 정의'!$D$2:$D$9,0)) -> 즐라탄 이브라히모비치 · 호나우지뉴 · 디에고 마라도나 | AB3: =ROUND(100*(1-SQRT(((S3-'포지션 정의'!$N$2)^2+(T3-'포지션 정의'!$O$2)^2+(U3-'포지션 정의'!$P$2)^2)/3)/'판정 기준'!$B$7),0) -> 69 | AC3: =ROUND(100*(1-SQRT(((S3-'포지션 정의'!$N$3)^2+(T3-'포지션 정의'!$O$3)^2+(U3-'포지션 정의'!$P$3)^2)/3)/'판정 기준'!$B$7),0) -> 74 | AD3: =ROUND(100*(1-SQRT(((S3-'포지션 정의'!$N$4)^2+(T3-'포지션 정의'!$O$4)^2+(U3-'포지션 정의'!$P$4)^2)/3)/'판정 기준'!$B$7),0) -> 78 | AE3: =ROUND(100*(1-SQRT(((S3-'포지션 정의'!$N$5)^2+(T3-'포지션 정의'!$O$5)^2+(U3-'포지션 정의'!$P$5)^2)/3)/'판정 기준'!$B$7),0) -> 94 | AF3: =ROUND(100*(1-SQRT(((S3-'포지션 정의'!$N$6)^2+(T3-'포지션 정의'!$O$6)^2+(U3-'포지션 정의'!$P$6)^2)/3)/'판정 기준'!$B$7),0) -> 82 | AG3: =ROUND(100*(1-SQRT(((S3-'포지션 정의'!$N$7)^2+(T3-'포지션 정의'!$O$7)^2+(U3-'포지션 정의'!$P$7)^2)/3)/'판정 기준'!$B$7),0) -> 78 | AH3: =ROUND(100*(1-SQRT(((S3-'포지션 정의'!$N$8)^2+(T3-'포지션 정의'!$O$8)^2+(U3-'포지션 정의'!$P$8)^2)/3)/'판정 기준'!$B$7),0) -> 72 | AI3: =ROUND(100*(1-SQRT(((S3-'포지션 정의'!$N$9)^2+(T3-'포지션 정의'!$O$9)^2+(U3-'포지션 정의'!$P$9)^2)/3)/'판정 기준'!$B$7),0) -> 85 | AJ3: =IF(G3>='판정 기준'!$B$8,"경기긴장도, ","")&IF(Q3>='판정 기준'!$B$8,"사회적 도움 활용, ","")&IF(K3>='판정 기준'!$B$8,"경기 준비 능력, ","")&IF(N3>='판정 기준'!$B$8,"실수 후 회복력, ","")&IF(P3>='판정 기준'!$B$8,"자기 통제력, ","") -> 경기긴장도, 사회적 도움 활용, 실수 후 회복력, | AK3: =IF(AND(G3<'판정 기준'!$B$8,OR(AJ3<>"",AP3<>"경기긴장도")),G3,0) -> 0 | AL3: =IF(AND(Q3<'판정 기준'!$B$8,OR(AJ3<>"",AP3<>"사회적 도움 활용")),Q3,0) -> 0 | AM3: =IF(AND(K3<'판정 기준'!$B$8,OR(AJ3<>"",AP3<>"경기 준비 능력")),K3,0) -> 4 | AN3: =IF(AND(N3<'판정 기준'!$B$8,OR(AJ3<>"",AP3<>"실수 후 회복력")),N3,0) -> 0 | AO3: =IF(AND(P3<'판정 기준'!$B$8,OR(AJ3<>"",AP3<>"자기 통제력")),P3,0) -> 3.5 | AP3: =IF(Q3=MAX(G3,Q3,K3,N3,P3),"사회적 도움 활용",IF(P3=MAX(G3,Q3,K3,N3,P3),"자기 통제력",IF(G3=MAX(G3,Q3,K3,N3,P3),"경기긴장도",IF(K3=MAX(G3,Q3,K3,N3,P3),"경기 준비 능력","실수 후 회복력")))) -> 실수 후 회복력
A4: 이준후 | B4: 남 | C4: 서울세일중학교 | D4: 46263 | E4: PHV 1 | F4: 4.5 | G4: 4.3 | H4: 4 | I4: 4.4 | J4: 3.8 | K4: 4.6 | L4: 4.2 | M4: 5 | N4: 4.6 | O4: 4.3 | P4: 4.3 | Q4: 4.6 | R4: 6 | S4: =AVERAGE(G4:J4) -> 4.125 | T4: =AVERAGE(K4:M4) -> 4.6 | U4: =AVERAGE(N4:O4) -> 4.45 | V4: =IF(S4>='판정 기준'!$B$3,"H","L")&IF(T4>='판정 기준'!$B$3,"H","L")&IF(U4>='판정 기준'!$B$3,"H","L") -> LHL | W4: =INDEX('포지션 정의'!$A$2:$A$9,MATCH(V4,'포지션 정의'!$D$2:$D$9,0)) -> A | X4: =INDEX('포지션 정의'!$B$2:$B$9,MATCH(V4,'포지션 정의'!$D$2:$D$9,0)) -> 섬세한 준비형 | Y4: =IF(AJ4="","가장 높은 지표: "&AP4,LEFT(AJ4,LEN(AJ4)-2)) -> 가장 높은 지표: 사회적 도움 활용 | Z4: =IF(MAX(AK4:AO4)=0,"심화: "&IF(N4=MIN(G4,Q4,K4,N4,P4),"실수 후 회복력",IF(K4=MIN(G4,Q4,K4,N4,P4),"경기 준비 능력",IF(G4=MIN(G4,Q4,K4,N4,P4),"경기긴장도",IF(P4=MIN(G4,Q4,K4,N4,P4),"자기 통제력","사회적 도움 활용")))),IF(MAX(AK4:AO4)>='판정 기준'!$B$8-'판정 기준'!$B$4,IF(AN4=MAX(AK4:AO4),"실수 후 회복력",IF(AM4=MAX(AK4:AO4),"경기 준비 능력",IF(AK4=MAX(AK4:AO4),"경기긴장도",IF(AO4=MAX(AK4:AO4),"자기 통제력","사회적 도움 활용")))),IF(AN4>0,"실수 후 회복력",IF(AM4>0,"경기 준비 능력",IF(AK4>0,"경기긴장도",IF(AO4>0,"자기 통제력","사회적 도움 활용")))))) -> 실수 후 회복력 | AA4: =INDEX('포지션 정의'!$L$2:$L$9,MATCH(V4,'포지션 정의'!$D$2:$D$9,0)) -> 로베르트 레반도프스키 · 제임스 밀너 · 마르틴 외데고르 | AB4: =ROUND(100*(1-SQRT(((S4-'포지션 정의'!$N$2)^2+(T4-'포지션 정의'!$O$2)^2+(U4-'포지션 정의'!$P$2)^2)/3)/'판정 기준'!$B$7),0) -> 89 | AC4: =ROUND(100*(1-SQRT(((S4-'포지션 정의'!$N$3)^2+(T4-'포지션 정의'!$O$3)^2+(U4-'포지션 정의'!$P$3)^2)/3)/'판정 기준'!$B$7),0) -> 84 | AD4: =ROUND(100*(1-SQRT(((S4-'포지션 정의'!$N$4)^2+(T4-'포지션 정의'!$O$4)^2+(U4-'포지션 정의'!$P$4)^2)/3)/'판정 기준'!$B$7),0) -> 83 | AE4: =ROUND(100*(1-SQRT(((S4-'포지션 정의'!$N$5)^2+(T4-'포지션 정의'!$O$5)^2+(U4-'포지션 정의'!$P$5)^2)/3)/'판정 기준'!$B$7),0) -> 82 | AF4: =ROUND(100*(1-SQRT(((S4-'포지션 정의'!$N$6)^2+(T4-'포지션 정의'!$O$6)^2+(U4-'포지션 정의'!$P$6)^2)/3)/'판정 기준'!$B$7),0) -> 87 | AG4: =ROUND(100*(1-SQRT(((S4-'포지션 정의'!$N$7)^2+(T4-'포지션 정의'!$O$7)^2+(U4-'포지션 정의'!$P$7)^2)/3)/'판정 기준'!$B$7),0) -> 88 | AH4: =ROUND(100*(1-SQRT(((S4-'포지션 정의'!$N$8)^2+(T4-'포지션 정의'!$O$8)^2+(U4-'포지션 정의'!$P$8)^2)/3)/'판정 기준'!$B$7),0) -> 88 | AI4: =ROUND(100*(1-SQRT(((S4-'포지션 정의'!$N$9)^2+(T4-'포지션 정의'!$O$9)^2+(U4-'포지션 정의'!$P$9)^2)/3)/'판정 기준'!$B$7),0) -> 83 | AJ4: =IF(G4>='판정 기준'!$B$8,"경기긴장도, ","")&IF(Q4>='판정 기준'!$B$8,"사회적 도움 활용, ","")&IF(K4>='판정 기준'!$B$8,"경기 준비 능력, ","")&IF(N4>='판정 기준'!$B$8,"실수 후 회복력, ","")&IF(P4>='판정 기준'!$B$8,"자기 통제력, ","") | AK4: =IF(AND(G4<'판정 기준'!$B$8,OR(AJ4<>"",AP4<>"경기긴장도")),G4,0) -> 4.3 | AL4: =IF(AND(Q4<'판정 기준'!$B$8,OR(AJ4<>"",AP4<>"사회적 도움 활용")),Q4,0) -> 0 | AM4: =IF(AND(K4<'판정 기준'!$B$8,OR(AJ4<>"",AP4<>"경기 준비 능력")),K4,0) -> 4.6 | AN4: =IF(AND(N4<'판정 기준'!$B$8,OR(AJ4<>"",AP4<>"실수 후 회복력")),N4,0) -> 4.6 | AO4: =IF(AND(P4<'판정 기준'!$B$8,OR(AJ4<>"",AP4<>"자기 통제력")),P4,0) -> 4.3 | AP4: =IF(Q4=MAX(G4,Q4,K4,N4,P4),"사회적 도움 활용",IF(P4=MAX(G4,Q4,K4,N4,P4),"자기 통제력",IF(G4=MAX(G4,Q4,K4,N4,P4),"경기긴장도",IF(K4=MAX(G4,Q4,K4,N4,P4),"경기 준비 능력","실수 후 회복력")))) -> 사회적 도움 활용
A5: 손신유 | B5: 남 | C5: 서울세일중학교 | D5: 46263 | E5: PHV -1 | F5: 3.4 | G5: 3.3 | H5: 3.2 | I5: 3.4 | J5: 3.3 | K5: 4.4 | L5: 4.5 | M5: 4.3 | N5: 2.7 | O5: 2.8 | P5: 3.3 | Q5: 4.8 | R5: 4 | S5: =AVERAGE(G5:J5) -> 3.3 | T5: =AVERAGE(K5:M5) -> 4.4 | U5: =AVERAGE(N5:O5) -> 2.75 | V5: =IF(S5>='판정 기준'!$B$3,"H","L")&IF(T5>='판정 기준'!$B$3,"H","L")&IF(U5>='판정 기준'!$B$3,"H","L") -> LLL | W5: =INDEX('포지션 정의'!$A$2:$A$9,MATCH(V5,'포지션 정의'!$D$2:$D$9,0)) -> G | X5: =INDEX('포지션 정의'!$B$2:$B$9,MATCH(V5,'포지션 정의'!$D$2:$D$9,0)) -> 스펀지 흡수형 | Y5: =IF(AJ5="","가장 높은 지표: "&AP5,LEFT(AJ5,LEN(AJ5)-2)) -> 사회적 도움 활용 | Z5: =IF(MAX(AK5:AO5)=0,"심화: "&IF(N5=MIN(G5,Q5,K5,N5,P5),"실수 후 회복력",IF(K5=MIN(G5,Q5,K5,N5,P5),"경기 준비 능력",IF(G5=MIN(G5,Q5,K5,N5,P5),"경기긴장도",IF(P5=MIN(G5,Q5,K5,N5,P5),"자기 통제력","사회적 도움 활용")))),IF(MAX(AK5:AO5)>='판정 기준'!$B$8-'판정 기준'!$B$4,IF(AN5=MAX(AK5:AO5),"실수 후 회복력",IF(AM5=MAX(AK5:AO5),"경기 준비 능력",IF(AK5=MAX(AK5:AO5),"경기긴장도",IF(AO5=MAX(AK5:AO5),"자기 통제력","사회적 도움 활용")))),IF(AN5>0,"실수 후 회복력",IF(AM5>0,"경기 준비 능력",IF(AK5>0,"경기긴장도",IF(AO5>0,"자기 통제력","사회적 도움 활용")))))) -> 실수 후 회복력 | AA5: =INDEX('포지션 정의'!$L$2:$L$9,MATCH(V5,'포지션 정의'!$D$2:$D$9,0)) -> 디디에 드로그바 · 앙투안 그리즈만 · 모하메드 살라 | AB5: =ROUND(100*(1-SQRT(((S5-'포지션 정의'!$N$2)^2+(T5-'포지션 정의'!$O$2)^2+(U5-'포지션 정의'!$P$2)^2)/3)/'판정 기준'!$B$7),0) -> 84 | AC5: =ROUND(100*(1-SQRT(((S5-'포지션 정의'!$N$3)^2+(T5-'포지션 정의'!$O$3)^2+(U5-'포지션 정의'!$P$3)^2)/3)/'판정 기준'!$B$7),0) -> 73 | AD5: =ROUND(100*(1-SQRT(((S5-'포지션 정의'!$N$4)^2+(T5-'포지션 정의'!$O$4)^2+(U5-'포지션 정의'!$P$4)^2)/3)/'판정 기준'!$B$7),0) -> 74 | AE5: =ROUND(100*(1-SQRT(((S5-'포지션 정의'!$N$5)^2+(T5-'포지션 정의'!$O$5)^2+(U5-'포지션 정의'!$P$5)^2)/3)/'판정 기준'!$B$7),0) -> 64 | AF5: =ROUND(100*(1-SQRT(((S5-'포지션 정의'!$N$6)^2+(T5-'포지션 정의'!$O$6)^2+(U5-'포지션 정의'!$P$6)^2)/3)/'판정 기준'!$B$7),0) -> 70 | AG5: =ROUND(100*(1-SQRT(((S5-'포지션 정의'!$N$7)^2+(T5-'포지션 정의'!$O$7)^2+(U5-'포지션 정의'!$P$7)^2)/3)/'판정 기준'!$B$7),0) -> 70 | AH5: =ROUND(100*(1-SQRT(((S5-'포지션 정의'!$N$8)^2+(T5-'포지션 정의'!$O$8)^2+(U5-'포지션 정의'!$P$8)^2)/3)/'판정 기준'!$B$7),0) -> 85 | AI5: =ROUND(100*(1-SQRT(((S5-'포지션 정의'!$N$9)^2+(T5-'포지션 정의'!$O$9)^2+(U5-'포지션 정의'!$P$9)^2)/3)/'판정 기준'!$B$7),0) -> 63 | AJ5: =IF(G5>='판정 기준'!$B$8,"경기긴장도, ","")&IF(Q5>='판정 기준'!$B$8,"사회적 도움 활용, ","")&IF(K5>='판정 기준'!$B$8,"경기 준비 능력, ","")&IF(N5>='판정 기준'!$B$8,"실수 후 회복력, ","")&IF(P5>='판정 기준'!$B$8,"자기 통제력, ","") -> 사회적 도움 활용, | AK5: =IF(AND(G5<'판정 기준'!$B$8,OR(AJ5<>"",AP5<>"경기긴장도")),G5,0) -> 3.3 | AL5: =IF(AND(Q5<'판정 기준'!$B$8,OR(AJ5<>"",AP5<>"사회적 도움 활용")),Q5,0) -> 0 | AM5: =IF(AND(K5<'판정 기준'!$B$8,OR(AJ5<>"",AP5<>"경기 준비 능력")),K5,0) -> 4.4 | AN5: =IF(AND(N5<'판정 기준'!$B$8,OR(AJ5<>"",AP5<>"실수 후 회복력")),N5,0) -> 2.7 | AO5: =IF(AND(P5<'판정 기준'!$B$8,OR(AJ5<>"",AP5<>"자기 통제력")),P5,0) -> 3.3 | AP5: =IF(Q5=MAX(G5,Q5,K5,N5,P5),"사회적 도움 활용",IF(P5=MAX(G5,Q5,K5,N5,P5),"자기 통제력",IF(G5=MAX(G5,Q5,K5,N5,P5),"경기긴장도",IF(K5=MAX(G5,Q5,K5,N5,P5),"경기 준비 능력","실수 후 회복력")))) -> 사회적 도움 활용
A6: 유선민 | B6: 남 | C6: 경기김포FC U12 | D6: 46256 | E6: PHV -2 | F6: 4.8 | G6: 4.9 | H6: 5.2 | I6: 5.2 | J6: 4.5 | K6: 4.7 | L6: 4.5 | M6: 4.9 | N6: 4.7 | O6: 5.2 | P6: 4.7 | Q6: 5.2 | R6: 5 | S6: =AVERAGE(G6:J6) -> 4.95 | T6: =AVERAGE(K6:M6) -> 4.7 | U6: =AVERAGE(N6:O6) -> 4.95 | V6: =IF(S6>='판정 기준'!$B$3,"H","L")&IF(T6>='판정 기준'!$B$3,"H","L")&IF(U6>='판정 기준'!$B$3,"H","L") -> HHH | W6: =INDEX('포지션 정의'!$A$2:$A$9,MATCH(V6,'포지션 정의'!$D$2:$D$9,0)) -> H | X6: =INDEX('포지션 정의'!$B$2:$B$9,MATCH(V6,'포지션 정의'!$D$2:$D$9,0)) -> 올라운드 밸런스형 | Y6: =IF(AJ6="","가장 높은 지표: "&AP6,LEFT(AJ6,LEN(AJ6)-2)) -> 경기긴장도, 사회적 도움 활용 | Z6: =IF(MAX(AK6:AO6)=0,"심화: "&IF(N6=MIN(G6,Q6,K6,N6,P6),"실수 후 회복력",IF(K6=MIN(G6,Q6,K6,N6,P6),"경기 준비 능력",IF(G6=MIN(G6,Q6,K6,N6,P6),"경기긴장도",IF(P6=MIN(G6,Q6,K6,N6,P6),"자기 통제력","사회적 도움 활용")))),IF(MAX(AK6:AO6)>='판정 기준'!$B$8-'판정 기준'!$B$4,IF(AN6=MAX(AK6:AO6),"실수 후 회복력",IF(AM6=MAX(AK6:AO6),"경기 준비 능력",IF(AK6=MAX(AK6:AO6),"경기긴장도",IF(AO6=MAX(AK6:AO6),"자기 통제력","사회적 도움 활용")))),IF(AN6>0,"실수 후 회복력",IF(AM6>0,"경기 준비 능력",IF(AK6>0,"경기긴장도",IF(AO6>0,"자기 통제력","사회적 도움 활용")))))) -> 실수 후 회복력 | AA6: =INDEX('포지션 정의'!$L$2:$L$9,MATCH(V6,'포지션 정의'!$D$2:$D$9,0)) -> 크리스티아누 호날두 · 루카 모드리치 · 버질 반 다이크 | AB6: =ROUND(100*(1-SQRT(((S6-'포지션 정의'!$N$2)^2+(T6-'포지션 정의'!$O$2)^2+(U6-'포지션 정의'!$P$2)^2)/3)/'판정 기준'!$B$7),0) -> 80 | AC6: =ROUND(100*(1-SQRT(((S6-'포지션 정의'!$N$3)^2+(T6-'포지션 정의'!$O$3)^2+(U6-'포지션 정의'!$P$3)^2)/3)/'판정 기준'!$B$7),0) -> 85 | AD6: =ROUND(100*(1-SQRT(((S6-'포지션 정의'!$N$4)^2+(T6-'포지션 정의'!$O$4)^2+(U6-'포지션 정의'!$P$4)^2)/3)/'판정 기준'!$B$7),0) -> 83 | AE6: =ROUND(100*(1-SQRT(((S6-'포지션 정의'!$N$5)^2+(T6-'포지션 정의'!$O$5)^2+(U6-'포지션 정의'!$P$5)^2)/3)/'판정 기준'!$B$7),0) -> 89 | AF6: =ROUND(100*(1-SQRT(((S6-'포지션 정의'!$N$6)^2+(T6-'포지션 정의'!$O$6)^2+(U6-'포지션 정의'!$P$6)^2)/3)/'판정 기준'!$B$7),0) -> 83 | AG6: =ROUND(100*(1-SQRT(((S6-'포지션 정의'!$N$7)^2+(T6-'포지션 정의'!$O$7)^2+(U6-'포지션 정의'!$P$7)^2)/3)/'판정 기준'!$B$7),0) -> 85 | AH6: =ROUND(100*(1-SQRT(((S6-'포지션 정의'!$N$8)^2+(T6-'포지션 정의'!$O$8)^2+(U6-'포지션 정의'!$P$8)^2)/3)/'판정 기준'!$B$7),0) -> 79 | AI6: =ROUND(100*(1-SQRT(((S6-'포지션 정의'!$N$9)^2+(T6-'포지션 정의'!$O$9)^2+(U6-'포지션 정의'!$P$9)^2)/3)/'판정 기준'!$B$7),0) -> 93 | AJ6: =IF(G6>='판정 기준'!$B$8,"경기긴장도, ","")&IF(Q6>='판정 기준'!$B$8,"사회적 도움 활용, ","")&IF(K6>='판정 기준'!$B$8,"경기 준비 능력, ","")&IF(N6>='판정 기준'!$B$8,"실수 후 회복력, ","")&IF(P6>='판정 기준'!$B$8,"자기 통제력, ","") -> 경기긴장도, 사회적 도움 활용, | AK6: =IF(AND(G6<'판정 기준'!$B$8,OR(AJ6<>"",AP6<>"경기긴장도")),G6,0) -> 0 | AL6: =IF(AND(Q6<'판정 기준'!$B$8,OR(AJ6<>"",AP6<>"사회적 도움 활용")),Q6,0) -> 0 | AM6: =IF(AND(K6<'판정 기준'!$B$8,OR(AJ6<>"",AP6<>"경기 준비 능력")),K6,0) -> 4.7 | AN6: =IF(AND(N6<'판정 기준'!$B$8,OR(AJ6<>"",AP6<>"실수 후 회복력")),N6,0) -> 4.7 | AO6: =IF(AND(P6<'판정 기준'!$B$8,OR(AJ6<>"",AP6<>"자기 통제력")),P6,0) -> 4.7 | AP6: =IF(Q6=MAX(G6,Q6,K6,N6,P6),"사회적 도움 활용",IF(P6=MAX(G6,Q6,K6,N6,P6),"자기 통제력",IF(G6=MAX(G6,Q6,K6,N6,P6),"경기긴장도",IF(K6=MAX(G6,Q6,K6,N6,P6),"경기 준비 능력","실수 후 회복력")))) -> 사회적 도움 활용
A7: 유정훈 | B7: 남 | C7: 경기양주 EHFC U15 | D7: 46256 | E7: PHV -1 | F7: 4.3 | G7: 4.4 | H7: 4.5 | I7: 4.6 | J7: 4 | K7: 4.4 | L7: 4 | M7: 4.7 | N7: 4.6 | O7: 4.2 | P7: 3.8 | Q7: 4.6 | R7: 5 | S7: =AVERAGE(G7:J7) -> 4.375 | T7: =AVERAGE(K7:M7) -> 4.3666667 | U7: =AVERAGE(N7:O7) -> 4.4 | V7: =IF(S7>='판정 기준'!$B$3,"H","L")&IF(T7>='판정 기준'!$B$3,"H","L")&IF(U7>='판정 기준'!$B$3,"H","L") -> LLL | W7: =INDEX('포지션 정의'!$A$2:$A$9,MATCH(V7,'포지션 정의'!$D$2:$D$9,0)) -> G | X7: =INDEX('포지션 정의'!$B$2:$B$9,MATCH(V7,'포지션 정의'!$D$2:$D$9,0)) -> 스펀지 흡수형 | Y7: =IF(AJ7="","가장 높은 지표: "&AP7,LEFT(AJ7,LEN(AJ7)-2)) -> 가장 높은 지표: 사회적 도움 활용 | Z7: =IF(MAX(AK7:AO7)=0,"심화: "&IF(N7=MIN(G7,Q7,K7,N7,P7),"실수 후 회복력",IF(K7=MIN(G7,Q7,K7,N7,P7),"경기 준비 능력",IF(G7=MIN(G7,Q7,K7,N7,P7),"경기긴장도",IF(P7=MIN(G7,Q7,K7,N7,P7),"자기 통제력","사회적 도움 활용")))),IF(MAX(AK7:AO7)>='판정 기준'!$B$8-'판정 기준'!$B$4,IF(AN7=MAX(AK7:AO7),"실수 후 회복력",IF(AM7=MAX(AK7:AO7),"경기 준비 능력",IF(AK7=MAX(AK7:AO7),"경기긴장도",IF(AO7=MAX(AK7:AO7),"자기 통제력","사회적 도움 활용")))),IF(AN7>0,"실수 후 회복력",IF(AM7>0,"경기 준비 능력",IF(AK7>0,"경기긴장도",IF(AO7>0,"자기 통제력","사회적 도움 활용")))))) -> 실수 후 회복력 | AA7: =INDEX('포지션 정의'!$L$2:$L$9,MATCH(V7,'포지션 정의'!$D$2:$D$9,0)) -> 디디에 드로그바 · 앙투안 그리즈만 · 모하메드 살라 | AB7: =ROUND(100*(1-SQRT(((S7-'포지션 정의'!$N$2)^2+(T7-'포지션 정의'!$O$2)^2+(U7-'포지션 정의'!$P$2)^2)/3)/'판정 기준'!$B$7),0) -> 86 | AC7: =ROUND(100*(1-SQRT(((S7-'포지션 정의'!$N$3)^2+(T7-'포지션 정의'!$O$3)^2+(U7-'포지션 정의'!$P$3)^2)/3)/'판정 기준'!$B$7),0) -> 85 | AD7: =ROUND(100*(1-SQRT(((S7-'포지션 정의'!$N$4)^2+(T7-'포지션 정의'!$O$4)^2+(U7-'포지션 정의'!$P$4)^2)/3)/'판정 기준'!$B$7),0) -> 87 | AE7: =ROUND(100*(1-SQRT(((S7-'포지션 정의'!$N$5)^2+(T7-'포지션 정의'!$O$5)^2+(U7-'포지션 정의'!$P$5)^2)/3)/'판정 기준'!$B$7),0) -> 85 | AF7: =ROUND(100*(1-SQRT(((S7-'포지션 정의'!$N$6)^2+(T7-'포지션 정의'!$O$6)^2+(U7-'포지션 정의'!$P$6)^2)/3)/'판정 기준'!$B$7),0) -> 87 | AG7: =ROUND(100*(1-SQRT(((S7-'포지션 정의'!$N$7)^2+(T7-'포지션 정의'!$O$7)^2+(U7-'포지션 정의'!$P$7)^2)/3)/'판정 기준'!$B$7),0) -> 85 | AH7: =ROUND(100*(1-SQRT(((S7-'포지션 정의'!$N$8)^2+(T7-'포지션 정의'!$O$8)^2+(U7-'포지션 정의'!$P$8)^2)/3)/'판정 기준'!$B$7),0) -> 88 | AI7: =ROUND(100*(1-SQRT(((S7-'포지션 정의'!$N$9)^2+(T7-'포지션 정의'!$O$9)^2+(U7-'포지션 정의'!$P$9)^2)/3)/'판정 기준'!$B$7),0) -> 84 | AJ7: =IF(G7>='판정 기준'!$B$8,"경기긴장도, ","")&IF(Q7>='판정 기준'!$B$8,"사회적 도움 활용, ","")&IF(K7>='판정 기준'!$B$8,"경기 준비 능력, ","")&IF(N7>='판정 기준'!$B$8,"실수 후 회복력, ","")&IF(P7>='판정 기준'!$B$8,"자기 통제력, ","") | AK7: =IF(AND(G7<'판정 기준'!$B$8,OR(AJ7<>"",AP7<>"경기긴장도")),G7,0) -> 4.4 | AL7: =IF(AND(Q7<'판정 기준'!$B$8,OR(AJ7<>"",AP7<>"사회적 도움 활용")),Q7,0) -> 0 | AM7: =IF(AND(K7<'판정 기준'!$B$8,OR(AJ7<>"",AP7<>"경기 준비 능력")),K7,0) -> 4.4 | AN7: =IF(AND(N7<'판정 기준'!$B$8,OR(AJ7<>"",AP7<>"실수 후 회복력")),N7,0) -> 4.6 | AO7: =IF(AND(P7<'판정 기준'!$B$8,OR(AJ7<>"",AP7<>"자기 통제력")),P7,0) -> 3.8 | AP7: =IF(Q7=MAX(G7,Q7,K7,N7,P7),"사회적 도움 활용",IF(P7=MAX(G7,Q7,K7,N7,P7),"자기 통제력",IF(G7=MAX(G7,Q7,K7,N7,P7),"경기긴장도",IF(K7=MAX(G7,Q7,K7,N7,P7),"경기 준비 능력","실수 후 회복력")))) -> 사회적 도움 활용
A8: 백규헌 | B8: 남 | C8: 경기양주 EHFC U15 | D8: 46256 | E8: PHV -2 | F8: 4.2 | G8: 4.3 | H8: 4.5 | I8: 4.6 | J8: 4.2 | K8: 3 | L8: 3 | M8: 3 | N8: 5.3 | O8: 5.3 | P8: 4 | Q8: 4.4 | R8: 5.3 | S8: =AVERAGE(G8:J8) -> 4.4 | T8: =AVERAGE(K8:M8) -> 3 | U8: =AVERAGE(N8:O8) -> 5.3 | V8: =IF(S8>='판정 기준'!$B$3,"H","L")&IF(T8>='판정 기준'!$B$3,"H","L")&IF(U8>='판정 기준'!$B$3,"H","L") -> LLH | W8: =INDEX('포지션 정의'!$A$2:$A$9,MATCH(V8,'포지션 정의'!$D$2:$D$9,0)) -> E | X8: =INDEX('포지션 정의'!$B$2:$B$9,MATCH(V8,'포지션 정의'!$D$2:$D$9,0)) -> 오뚝이 회복형 | Y8: =IF(AJ8="","가장 높은 지표: "&AP8,LEFT(AJ8,LEN(AJ8)-2)) -> 실수 후 회복력 | Z8: =IF(MAX(AK8:AO8)=0,"심화: "&IF(N8=MIN(G8,Q8,K8,N8,P8),"실수 후 회복력",IF(K8=MIN(G8,Q8,K8,N8,P8),"경기 준비 능력",IF(G8=MIN(G8,Q8,K8,N8,P8),"경기긴장도",IF(P8=MIN(G8,Q8,K8,N8,P8),"자기 통제력","사회적 도움 활용")))),IF(MAX(AK8:AO8)>='판정 기준'!$B$8-'판정 기준'!$B$4,IF(AN8=MAX(AK8:AO8),"실수 후 회복력",IF(AM8=MAX(AK8:AO8),"경기 준비 능력",IF(AK8=MAX(AK8:AO8),"경기긴장도",IF(AO8=MAX(AK8:AO8),"자기 통제력","사회적 도움 활용")))),IF(AN8>0,"실수 후 회복력",IF(AM8>0,"경기 준비 능력",IF(AK8>0,"경기긴장도",IF(AO8>0,"자기 통제력","사회적 도움 활용")))))) -> 경기 준비 능력 | AA8: =INDEX('포지션 정의'!$L$2:$L$9,MATCH(V8,'포지션 정의'!$D$2:$D$9,0)) -> 올리비에 지루 · 디에고 포를란 · 라다멜 팔카오 | AB8: =ROUND(100*(1-SQRT(((S8-'포지션 정의'!$N$2)^2+(T8-'포지션 정의'!$O$2)^2+(U8-'포지션 정의'!$P$2)^2)/3)/'판정 기준'!$B$7),0) -> 68 | AC8: =ROUND(100*(1-SQRT(((S8-'포지션 정의'!$N$3)^2+(T8-'포지션 정의'!$O$3)^2+(U8-'포지션 정의'!$P$3)^2)/3)/'판정 기준'!$B$7),0) -> 68 | AD8: =ROUND(100*(1-SQRT(((S8-'포지션 정의'!$N$4)^2+(T8-'포지션 정의'!$O$4)^2+(U8-'포지션 정의'!$P$4)^2)/3)/'판정 기준'!$B$7),0) -> 78 | AE8: =ROUND(100*(1-SQRT(((S8-'포지션 정의'!$N$5)^2+(T8-'포지션 정의'!$O$5)^2+(U8-'포지션 정의'!$P$5)^2)/3)/'판정 기준'!$B$7),0) -> 87 | AF8: =ROUND(100*(1-SQRT(((S8-'포지션 정의'!$N$6)^2+(T8-'포지션 정의'!$O$6)^2+(U8-'포지션 정의'!$P$6)^2)/3)/'판정 기준'!$B$7),0) -> 88 | AG8: =ROUND(100*(1-SQRT(((S8-'포지션 정의'!$N$7)^2+(T8-'포지션 정의'!$O$7)^2+(U8-'포지션 정의'!$P$7)^2)/3)/'판정 기준'!$B$7),0) -> 74 | AH8: =ROUND(100*(1-SQRT(((S8-'포지션 정의'!$N$8)^2+(T8-'포지션 정의'!$O$8)^2+(U8-'포지션 정의'!$P$8)^2)/3)/'판정 기준'!$B$7),0) -> 79 | AI8: =ROUND(100*(1-SQRT(((S8-'포지션 정의'!$N$9)^2+(T8-'포지션 정의'!$O$9)^2+(U8-'포지션 정의'!$P$9)^2)/3)/'판정 기준'!$B$7),0) -> 73 | AJ8: =IF(G8>='판정 기준'!$B$8,"경기긴장도, ","")&IF(Q8>='판정 기준'!$B$8,"사회적 도움 활용, ","")&IF(K8>='판정 기준'!$B$8,"경기 준비 능력, ","")&IF(N8>='판정 기준'!$B$8,"실수 후 회복력, ","")&IF(P8>='판정 기준'!$B$8,"자기 통제력, ","") -> 실수 후 회복력, | AK8: =IF(AND(G8<'판정 기준'!$B$8,OR(AJ8<>"",AP8<>"경기긴장도")),G8,0) -> 4.3 | AL8: =IF(AND(Q8<'판정 기준'!$B$8,OR(AJ8<>"",AP8<>"사회적 도움 활용")),Q8,0) -> 4.4 | AM8: =IF(AND(K8<'판정 기준'!$B$8,OR(AJ8<>"",AP8<>"경기 준비 능력")),K8,0) -> 3 | AN8: =IF(AND(N8<'판정 기준'!$B$8,OR(AJ8<>"",AP8<>"실수 후 회복력")),N8,0) -> 0 | AO8: =IF(AND(P8<'판정 기준'!$B$8,OR(AJ8<>"",AP8<>"자기 통제력")),P8,0) -> 4 | AP8: =IF(Q8=MAX(G8,Q8,K8,N8,P8),"사회적 도움 활용",IF(P8=MAX(G8,Q8,K8,N8,P8),"자기 통제력",IF(G8=MAX(G8,Q8,K8,N8,P8),"경기긴장도",IF(K8=MAX(G8,Q8,K8,N8,P8),"경기 준비 능력","실수 후 회복력")))) -> 실수 후 회복력
A9: 송현우 | B9: 남 | C9: 경기양주 EHFC U15 | D9: 46256 | E9: PHV 0 | F9: 3.7 | G9: 3.4 | H9: 3.3 | I9: 3.8 | J9: 3 | K9: 4.5 | L9: 4.7 | M9: 4.4 | N9: 3.1 | O9: 3.7 | P9: 3.8 | Q9: 5.2 | R9: 5.3 | S9: =AVERAGE(G9:J9) -> 3.375 | T9: =AVERAGE(K9:M9) -> 4.5333333 | U9: =AVERAGE(N9:O9) -> 3.4 | V9: =IF(S9>='판정 기준'!$B$3,"H","L")&IF(T9>='판정 기준'!$B$3,"H","L")&IF(U9>='판정 기준'!$B$3,"H","L") -> LHL | W9: =INDEX('포지션 정의'!$A$2:$A$9,MATCH(V9,'포지션 정의'!$D$2:$D$9,0)) -> A | X9: =INDEX('포지션 정의'!$B$2:$B$9,MATCH(V9,'포지션 정의'!$D$2:$D$9,0)) -> 섬세한 준비형 | Y9: =IF(AJ9="","가장 높은 지표: "&AP9,LEFT(AJ9,LEN(AJ9)-2)) -> 사회적 도움 활용 | Z9: =IF(MAX(AK9:AO9)=0,"심화: "&IF(N9=MIN(G9,Q9,K9,N9,P9),"실수 후 회복력",IF(K9=MIN(G9,Q9,K9,N9,P9),"경기 준비 능력",IF(G9=MIN(G9,Q9,K9,N9,P9),"경기긴장도",IF(P9=MIN(G9,Q9,K9,N9,P9),"자기 통제력","사회적 도움 활용")))),IF(MAX(AK9:AO9)>='판정 기준'!$B$8-'판정 기준'!$B$4,IF(AN9=MAX(AK9:AO9),"실수 후 회복력",IF(AM9=MAX(AK9:AO9),"경기 준비 능력",IF(AK9=MAX(AK9:AO9),"경기긴장도",IF(AO9=MAX(AK9:AO9),"자기 통제력","사회적 도움 활용")))),IF(AN9>0,"실수 후 회복력",IF(AM9>0,"경기 준비 능력",IF(AK9>0,"경기긴장도",IF(AO9>0,"자기 통제력","사회적 도움 활용")))))) -> 경기 준비 능력 | AA9: =INDEX('포지션 정의'!$L$2:$L$9,MATCH(V9,'포지션 정의'!$D$2:$D$9,0)) -> 로베르트 레반도프스키 · 제임스 밀너 · 마르틴 외데고르 | AB9: =ROUND(100*(1-SQRT(((S9-'포지션 정의'!$N$2)^2+(T9-'포지션 정의'!$O$2)^2+(U9-'포지션 정의'!$P$2)^2)/3)/'판정 기준'!$B$7),0) -> 90 | AC9: =ROUND(100*(1-SQRT(((S9-'포지션 정의'!$N$3)^2+(T9-'포지션 정의'!$O$3)^2+(U9-'포지션 정의'!$P$3)^2)/3)/'판정 기준'!$B$7),0) -> 77 | AD9: =ROUND(100*(1-SQRT(((S9-'포지션 정의'!$N$4)^2+(T9-'포지션 정의'!$O$4)^2+(U9-'포지션 정의'!$P$4)^2)/3)/'판정 기준'!$B$7),0) -> 77 | AE9: =ROUND(100*(1-SQRT(((S9-'포지션 정의'!$N$5)^2+(T9-'포지션 정의'!$O$5)^2+(U9-'포지션 정의'!$P$5)^2)/3)/'판정 기준'!$B$7),0) -> 69 | AF9: =ROUND(100*(1-SQRT(((S9-'포지션 정의'!$N$6)^2+(T9-'포지션 정의'!$O$6)^2+(U9-'포지션 정의'!$P$6)^2)/3)/'판정 기준'!$B$7),0) -> 77 | AG9: =ROUND(100*(1-SQRT(((S9-'포지션 정의'!$N$7)^2+(T9-'포지션 정의'!$O$7)^2+(U9-'포지션 정의'!$P$7)^2)/3)/'판정 기준'!$B$7),0) -> 77 | AH9: =ROUND(100*(1-SQRT(((S9-'포지션 정의'!$N$8)^2+(T9-'포지션 정의'!$O$8)^2+(U9-'포지션 정의'!$P$8)^2)/3)/'판정 기준'!$B$7),0) -> 89 | AI9: =ROUND(100*(1-SQRT(((S9-'포지션 정의'!$N$9)^2+(T9-'포지션 정의'!$O$9)^2+(U9-'포지션 정의'!$P$9)^2)/3)/'판정 기준'!$B$7),0) -> 69 | AJ9: =IF(G9>='판정 기준'!$B$8,"경기긴장도, ","")&IF(Q9>='판정 기준'!$B$8,"사회적 도움 활용, ","")&IF(K9>='판정 기준'!$B$8,"경기 준비 능력, ","")&IF(N9>='판정 기준'!$B$8,"실수 후 회복력, ","")&IF(P9>='판정 기준'!$B$8,"자기 통제력, ","") -> 사회적 도움 활용, | AK9: =IF(AND(G9<'판정 기준'!$B$8,OR(AJ9<>"",AP9<>"경기긴장도")),G9,0) -> 3.4 | AL9: =IF(AND(Q9<'판정 기준'!$B$8,OR(AJ9<>"",AP9<>"사회적 도움 활용")),Q9,0) -> 0 | AM9: =IF(AND(K9<'판정 기준'!$B$8,OR(AJ9<>"",AP9<>"경기 준비 능력")),K9,0) -> 4.5 | AN9: =IF(AND(N9<'판정 기준'!$B$8,OR(AJ9<>"",AP9<>"실수 후 회복력")),N9,0) -> 3.1 | AO9: =IF(AND(P9<'판정 기준'!$B$8,OR(AJ9<>"",AP9<>"자기 통제력")),P9,0) -> 3.8 | AP9: =IF(Q9=MAX(G9,Q9,K9,N9,P9),"사회적 도움 활용",IF(P9=MAX(G9,Q9,K9,N9,P9),"자기 통제력",IF(G9=MAX(G9,Q9,K9,N9,P9),"경기긴장도",IF(K9=MAX(G9,Q9,K9,N9,P9),"경기 준비 능력","실수 후 회복력")))) -> 사회적 도움 활용
A10: 이우빈 | B10: 남 | C10: 경기양주 EHFC U15 | D10: 46256 | E10: PHV 0 | F10: 4.7 | G10: 4.7 | H10: 3.8 | I10: 5.2 | J10: 4.7 | K10: 3.8 | L10: 3.5 | M10: 4 | N10: 5.3 | O10: 5.3 | P10: 5 | Q10: 5.4 | R10: 5.7 | S10: =AVERAGE(G10:J10) -> 4.6 | T10: =AVERAGE(K10:M10) -> 3.7666667 | U10: =AVERAGE(N10:O10) -> 5.3 | V10: =IF(S10>='판정 기준'!$B$3,"H","L")&IF(T10>='판정 기준'!$B$3,"H","L")&IF(U10>='판정 기준'!$B$3,"H","L") -> HLH | W10: =INDEX('포지션 정의'!$A$2:$A$9,MATCH(V10,'포지션 정의'!$D$2:$D$9,0)) -> D | X10: =INDEX('포지션 정의'!$B$2:$B$9,MATCH(V10,'포지션 정의'!$D$2:$D$9,0)) -> 실전 승부사형 | Y10: =IF(AJ10="","가장 높은 지표: "&AP10,LEFT(AJ10,LEN(AJ10)-2)) -> 사회적 도움 활용, 실수 후 회복력, 자기 통제력 | Z10: =IF(MAX(AK10:AO10)=0,"심화: "&IF(N10=MIN(G10,Q10,K10,N10,P10),"실수 후 회복력",IF(K10=MIN(G10,Q10,K10,N10,P10),"경기 준비 능력",IF(G10=MIN(G10,Q10,K10,N10,P10),"경기긴장도",IF(P10=MIN(G10,Q10,K10,N10,P10),"자기 통제력","사회적 도움 활용")))),IF(MAX(AK10:AO10)>='판정 기준'!$B$8-'판정 기준'!$B$4,IF(AN10=MAX(AK10:AO10),"실수 후 회복력",IF(AM10=MAX(AK10:AO10),"경기 준비 능력",IF(AK10=MAX(AK10:AO10),"경기긴장도",IF(AO10=MAX(AK10:AO10),"자기 통제력","사회적 도움 활용")))),IF(AN10>0,"실수 후 회복력",IF(AM10>0,"경기 준비 능력",IF(AK10>0,"경기긴장도",IF(AO10>0,"자기 통제력","사회적 도움 활용")))))) -> 경기긴장도 | AA10: =INDEX('포지션 정의'!$L$2:$L$9,MATCH(V10,'포지션 정의'!$D$2:$D$9,0)) -> 즐라탄 이브라히모비치 · 호나우지뉴 · 디에고 마라도나 | AB10: =ROUND(100*(1-SQRT(((S10-'포지션 정의'!$N$2)^2+(T10-'포지션 정의'!$O$2)^2+(U10-'포지션 정의'!$P$2)^2)/3)/'판정 기준'!$B$7),0) -> 74 | AC10: =ROUND(100*(1-SQRT(((S10-'포지션 정의'!$N$3)^2+(T10-'포지션 정의'!$O$3)^2+(U10-'포지션 정의'!$P$3)^2)/3)/'판정 기준'!$B$7),0) -> 75 | AD10: =ROUND(100*(1-SQRT(((S10-'포지션 정의'!$N$4)^2+(T10-'포지션 정의'!$O$4)^2+(U10-'포지션 정의'!$P$4)^2)/3)/'판정 기준'!$B$7),0) -> 81 | AE10: =ROUND(100*(1-SQRT(((S10-'포지션 정의'!$N$5)^2+(T10-'포지션 정의'!$O$5)^2+(U10-'포지션 정의'!$P$5)^2)/3)/'판정 기준'!$B$7),0) -> 93 | AF10: =ROUND(100*(1-SQRT(((S10-'포지션 정의'!$N$6)^2+(T10-'포지션 정의'!$O$6)^2+(U10-'포지션 정의'!$P$6)^2)/3)/'판정 기준'!$B$7),0) -> 91 | AG10: =ROUND(100*(1-SQRT(((S10-'포지션 정의'!$N$7)^2+(T10-'포지션 정의'!$O$7)^2+(U10-'포지션 정의'!$P$7)^2)/3)/'판정 기준'!$B$7),0) -> 81 | AH10: =ROUND(100*(1-SQRT(((S10-'포지션 정의'!$N$8)^2+(T10-'포지션 정의'!$O$8)^2+(U10-'포지션 정의'!$P$8)^2)/3)/'판정 기준'!$B$7),0) -> 80 | AI10: =ROUND(100*(1-SQRT(((S10-'포지션 정의'!$N$9)^2+(T10-'포지션 정의'!$O$9)^2+(U10-'포지션 정의'!$P$9)^2)/3)/'판정 기준'!$B$7),0) -> 82 | AJ10: =IF(G10>='판정 기준'!$B$8,"경기긴장도, ","")&IF(Q10>='판정 기준'!$B$8,"사회적 도움 활용, ","")&IF(K10>='판정 기준'!$B$8,"경기 준비 능력, ","")&IF(N10>='판정 기준'!$B$8,"실수 후 회복력, ","")&IF(P10>='판정 기준'!$B$8,"자기 통제력, ","") -> 사회적 도움 활용, 실수 후 회복력, 자기 통제력, | AK10: =IF(AND(G10<'판정 기준'!$B$8,OR(AJ10<>"",AP10<>"경기긴장도")),G10,0) -> 4.7 | AL10: =IF(AND(Q10<'판정 기준'!$B$8,OR(AJ10<>"",AP10<>"사회적 도움 활용")),Q10,0) -> 0 | AM10: =IF(AND(K10<'판정 기준'!$B$8,OR(AJ10<>"",AP10<>"경기 준비 능력")),K10,0) -> 3.8 | AN10: =IF(AND(N10<'판정 기준'!$B$8,OR(AJ10<>"",AP10<>"실수 후 회복력")),N10,0) -> 0 | AO10: =IF(AND(P10<'판정 기준'!$B$8,OR(AJ10<>"",AP10<>"자기 통제력")),P10,0) -> 0 | AP10: =IF(Q10=MAX(G10,Q10,K10,N10,P10),"사회적 도움 활용",IF(P10=MAX(G10,Q10,K10,N10,P10),"자기 통제력",IF(G10=MAX(G10,Q10,K10,N10,P10),"경기긴장도",IF(K10=MAX(G10,Q10,K10,N10,P10),"경기 준비 능력","실수 후 회복력")))) -> 사회적 도움 활용
A11: 박정준 | B11: 남 | C11: 경기양주 EHFC U15 | D11: 46256 | E11: PHV -1 | F11: 4.6 | G11: 4.2 | H11: 3.7 | I11: 5 | J11: 3.5 | K11: 4.5 | L11: 4.2 | M11: 4.9 | N11: 5.1 | O11: 5 | P11: 4.3 | Q11: 5.2 | R11: 5 | S11: =AVERAGE(G11:J11) -> 4.1 | T11: =AVERAGE(K11:M11) -> 4.5333333 | U11: =AVERAGE(N11:O11) -> 5.05 | V11: =IF(S11>='판정 기준'!$B$3,"H","L")&IF(T11>='판정 기준'!$B$3,"H","L")&IF(U11>='판정 기준'!$B$3,"H","L") -> LHH | W11: =INDEX('포지션 정의'!$A$2:$A$9,MATCH(V11,'포지션 정의'!$D$2:$D$9,0)) -> F | X11: =INDEX('포지션 정의'!$B$2:$B$9,MATCH(V11,'포지션 정의'!$D$2:$D$9,0)) -> 성실한 도전자형 | Y11: =IF(AJ11="","가장 높은 지표: "&AP11,LEFT(AJ11,LEN(AJ11)-2)) -> 사회적 도움 활용, 실수 후 회복력 | Z11: =IF(MAX(AK11:AO11)=0,"심화: "&IF(N11=MIN(G11,Q11,K11,N11,P11),"실수 후 회복력",IF(K11=MIN(G11,Q11,K11,N11,P11),"경기 준비 능력",IF(G11=MIN(G11,Q11,K11,N11,P11),"경기긴장도",IF(P11=MIN(G11,Q11,K11,N11,P11),"자기 통제력","사회적 도움 활용")))),IF(MAX(AK11:AO11)>='판정 기준'!$B$8-'판정 기준'!$B$4,IF(AN11=MAX(AK11:AO11),"실수 후 회복력",IF(AM11=MAX(AK11:AO11),"경기 준비 능력",IF(AK11=MAX(AK11:AO11),"경기긴장도",IF(AO11=MAX(AK11:AO11),"자기 통제력","사회적 도움 활용")))),IF(AN11>0,"실수 후 회복력",IF(AM11>0,"경기 준비 능력",IF(AK11>0,"경기긴장도",IF(AO11>0,"자기 통제력","사회적 도움 활용")))))) -> 경기 준비 능력 | AA11: =INDEX('포지션 정의'!$L$2:$L$9,MATCH(V11,'포지션 정의'!$D$2:$D$9,0)) -> 제이미 바디 · 은골로 캉테 · 박지성 | AB11: =ROUND(100*(1-SQRT(((S11-'포지션 정의'!$N$2)^2+(T11-'포지션 정의'!$O$2)^2+(U11-'포지션 정의'!$P$2)^2)/3)/'판정 기준'!$B$7),0) -> 83 | AC11: =ROUND(100*(1-SQRT(((S11-'포지션 정의'!$N$3)^2+(T11-'포지션 정의'!$O$3)^2+(U11-'포지션 정의'!$P$3)^2)/3)/'판정 기준'!$B$7),0) -> 79 | AD11: =ROUND(100*(1-SQRT(((S11-'포지션 정의'!$N$4)^2+(T11-'포지션 정의'!$O$4)^2+(U11-'포지션 정의'!$P$4)^2)/3)/'판정 기준'!$B$7),0) -> 79 | AE11: =ROUND(100*(1-SQRT(((S11-'포지션 정의'!$N$5)^2+(T11-'포지션 정의'!$O$5)^2+(U11-'포지션 정의'!$P$5)^2)/3)/'판정 기준'!$B$7),0) -> 85 | AF11: =ROUND(100*(1-SQRT(((S11-'포지션 정의'!$N$6)^2+(T11-'포지션 정의'!$O$6)^2+(U11-'포지션 정의'!$P$6)^2)/3)/'판정 기준'!$B$7),0) -> 91 | AG11: =ROUND(100*(1-SQRT(((S11-'포지션 정의'!$N$7)^2+(T11-'포지션 정의'!$O$7)^2+(U11-'포지션 정의'!$P$7)^2)/3)/'판정 기준'!$B$7),0) -> 91 | AH11: =ROUND(100*(1-SQRT(((S11-'포지션 정의'!$N$8)^2+(T11-'포지션 정의'!$O$8)^2+(U11-'포지션 정의'!$P$8)^2)/3)/'판정 기준'!$B$7),0) -> 83 | AI11: =ROUND(100*(1-SQRT(((S11-'포지션 정의'!$N$9)^2+(T11-'포지션 정의'!$O$9)^2+(U11-'포지션 정의'!$P$9)^2)/3)/'판정 기준'!$B$7),0) -> 85 | AJ11: =IF(G11>='판정 기준'!$B$8,"경기긴장도, ","")&IF(Q11>='판정 기준'!$B$8,"사회적 도움 활용, ","")&IF(K11>='판정 기준'!$B$8,"경기 준비 능력, ","")&IF(N11>='판정 기준'!$B$8,"실수 후 회복력, ","")&IF(P11>='판정 기준'!$B$8,"자기 통제력, ","") -> 사회적 도움 활용, 실수 후 회복력, | AK11: =IF(AND(G11<'판정 기준'!$B$8,OR(AJ11<>"",AP11<>"경기긴장도")),G11,0) -> 4.2 | AL11: =IF(AND(Q11<'판정 기준'!$B$8,OR(AJ11<>"",AP11<>"사회적 도움 활용")),Q11,0) -> 0 | AM11: =IF(AND(K11<'판정 기준'!$B$8,OR(AJ11<>"",AP11<>"경기 준비 능력")),K11,0) -> 4.5 | AN11: =IF(AND(N11<'판정 기준'!$B$8,OR(AJ11<>"",AP11<>"실수 후 회복력")),N11,0) -> 0 | AO11: =IF(AND(P11<'판정 기준'!$B$8,OR(AJ11<>"",AP11<>"자기 통제력")),P11,0) -> 4.3 | AP11: =IF(Q11=MAX(G11,Q11,K11,N11,P11),"사회적 도움 활용",IF(P11=MAX(G11,Q11,K11,N11,P11),"자기 통제력",IF(G11=MAX(G11,Q11,K11,N11,P11),"경기긴장도",IF(K11=MAX(G11,Q11,K11,N11,P11),"경기 준비 능력","실수 후 회복력")))) -> 사회적 도움 활용
A12: 안서진 | B12: 남 | C12: 경기양주 EHFC U15 | D12: 46256 | E12: PHV 0 | F12: 3.8 | G12: 3.4 | H12: 3 | I12: 4.4 | J12: 3 | K12: 4.8 | L12: 4.8 | M12: 4.7 | N12: 3.4 | O12: 4 | P12: 3.8 | Q12: 4.4 | R12: 4.7 | S12: =AVERAGE(G12:J12) -> 3.45 | T12: =AVERAGE(K12:M12) -> 4.7666667 | U12: =AVERAGE(N12:O12) -> 3.7 | V12: =IF(S12>='판정 기준'!$B$3,"H","L")&IF(T12>='판정 기준'!$B$3,"H","L")&IF(U12>='판정 기준'!$B$3,"H","L") -> LHL | W12: =INDEX('포지션 정의'!$A$2:$A$9,MATCH(V12,'포지션 정의'!$D$2:$D$9,0)) -> A | X12: =INDEX('포지션 정의'!$B$2:$B$9,MATCH(V12,'포지션 정의'!$D$2:$D$9,0)) -> 섬세한 준비형 | Y12: =IF(AJ12="","가장 높은 지표: "&AP12,LEFT(AJ12,LEN(AJ12)-2)) -> 경기 준비 능력 | Z12: =IF(MAX(AK12:AO12)=0,"심화: "&IF(N12=MIN(G12,Q12,K12,N12,P12),"실수 후 회복력",IF(K12=MIN(G12,Q12,K12,N12,P12),"경기 준비 능력",IF(G12=MIN(G12,Q12,K12,N12,P12),"경기긴장도",IF(P12=MIN(G12,Q12,K12,N12,P12),"자기 통제력","사회적 도움 활용")))),IF(MAX(AK12:AO12)>='판정 기준'!$B$8-'판정 기준'!$B$4,IF(AN12=MAX(AK12:AO12),"실수 후 회복력",IF(AM12=MAX(AK12:AO12),"경기 준비 능력",IF(AK12=MAX(AK12:AO12),"경기긴장도",IF(AO12=MAX(AK12:AO12),"자기 통제력","사회적 도움 활용")))),IF(AN12>0,"실수 후 회복력",IF(AM12>0,"경기 준비 능력",IF(AK12>0,"경기긴장도",IF(AO12>0,"자기 통제력","사회적 도움 활용")))))) -> 실수 후 회복력 | AA12: =INDEX('포지션 정의'!$L$2:$L$9,MATCH(V12,'포지션 정의'!$D$2:$D$9,0)) -> 로베르트 레반도프스키 · 제임스 밀너 · 마르틴 외데고르 | AB12: =ROUND(100*(1-SQRT(((S12-'포지션 정의'!$N$2)^2+(T12-'포지션 정의'!$O$2)^2+(U12-'포지션 정의'!$P$2)^2)/3)/'판정 기준'!$B$7),0) -> 93 | AC12: =ROUND(100*(1-SQRT(((S12-'포지션 정의'!$N$3)^2+(T12-'포지션 정의'!$O$3)^2+(U12-'포지션 정의'!$P$3)^2)/3)/'판정 기준'!$B$7),0) -> 79 | AD12: =ROUND(100*(1-SQRT(((S12-'포지션 정의'!$N$4)^2+(T12-'포지션 정의'!$O$4)^2+(U12-'포지션 정의'!$P$4)^2)/3)/'판정 기준'!$B$7),0) -> 77 | AE12: =ROUND(100*(1-SQRT(((S12-'포지션 정의'!$N$5)^2+(T12-'포지션 정의'!$O$5)^2+(U12-'포지션 정의'!$P$5)^2)/3)/'판정 기준'!$B$7),0) -> 71 | AF12: =ROUND(100*(1-SQRT(((S12-'포지션 정의'!$N$6)^2+(T12-'포지션 정의'!$O$6)^2+(U12-'포지션 정의'!$P$6)^2)/3)/'판정 기준'!$B$7),0) -> 79 | AG12: =ROUND(100*(1-SQRT(((S12-'포지션 정의'!$N$7)^2+(T12-'포지션 정의'!$O$7)^2+(U12-'포지션 정의'!$P$7)^2)/3)/'판정 기준'!$B$7),0) -> 82 | AH12: =ROUND(100*(1-SQRT(((S12-'포지션 정의'!$N$8)^2+(T12-'포지션 정의'!$O$8)^2+(U12-'포지션 정의'!$P$8)^2)/3)/'판정 기준'!$B$7),0) -> 88 | AI12: =ROUND(100*(1-SQRT(((S12-'포지션 정의'!$N$9)^2+(T12-'포지션 정의'!$O$9)^2+(U12-'포지션 정의'!$P$9)^2)/3)/'판정 기준'!$B$7),0) -> 73 | AJ12: =IF(G12>='판정 기준'!$B$8,"경기긴장도, ","")&IF(Q12>='판정 기준'!$B$8,"사회적 도움 활용, ","")&IF(K12>='판정 기준'!$B$8,"경기 준비 능력, ","")&IF(N12>='판정 기준'!$B$8,"실수 후 회복력, ","")&IF(P12>='판정 기준'!$B$8,"자기 통제력, ","") -> 경기 준비 능력, | AK12: =IF(AND(G12<'판정 기준'!$B$8,OR(AJ12<>"",AP12<>"경기긴장도")),G12,0) -> 3.4 | AL12: =IF(AND(Q12<'판정 기준'!$B$8,OR(AJ12<>"",AP12<>"사회적 도움 활용")),Q12,0) -> 4.4 | AM12: =IF(AND(K12<'판정 기준'!$B$8,OR(AJ12<>"",AP12<>"경기 준비 능력")),K12,0) -> 0 | AN12: =IF(AND(N12<'판정 기준'!$B$8,OR(AJ12<>"",AP12<>"실수 후 회복력")),N12,0) -> 3.4 | AO12: =IF(AND(P12<'판정 기준'!$B$8,OR(AJ12<>"",AP12<>"자기 통제력")),P12,0) -> 3.8 | AP12: =IF(Q12=MAX(G12,Q12,K12,N12,P12),"사회적 도움 활용",IF(P12=MAX(G12,Q12,K12,N12,P12),"자기 통제력",IF(G12=MAX(G12,Q12,K12,N12,P12),"경기긴장도",IF(K12=MAX(G12,Q12,K12,N12,P12),"경기 준비 능력","실수 후 회복력")))) -> 경기 준비 능력
A13: 이승환 | B13: 남 | C13: 서울신림중학교 | D13: 46248 | E13: PHV 1 | F13: 3.8 | G13: 4.2 | H13: 5.2 | I13: 4 | J13: 4.2 | K13: 3.9 | L13: 3.7 | M13: 4.1 | N13: 4 | O13: 4.7 | P13: 3 | Q13: 3.2 | R13: 5 | S13: =AVERAGE(G13:J13) -> 4.4 | T13: =AVERAGE(K13:M13) -> 3.9 | U13: =AVERAGE(N13:O13) -> 4.35 | V13: =IF(S13>='판정 기준'!$B$3,"H","L")&IF(T13>='판정 기준'!$B$3,"H","L")&IF(U13>='판정 기준'!$B$3,"H","L") -> LLL | W13: =INDEX('포지션 정의'!$A$2:$A$9,MATCH(V13,'포지션 정의'!$D$2:$D$9,0)) -> G | X13: =INDEX('포지션 정의'!$B$2:$B$9,MATCH(V13,'포지션 정의'!$D$2:$D$9,0)) -> 스펀지 흡수형 | Y13: =IF(AJ13="","가장 높은 지표: "&AP13,LEFT(AJ13,LEN(AJ13)-2)) -> 가장 높은 지표: 경기긴장도 | Z13: =IF(MAX(AK13:AO13)=0,"심화: "&IF(N13=MIN(G13,Q13,K13,N13,P13),"실수 후 회복력",IF(K13=MIN(G13,Q13,K13,N13,P13),"경기 준비 능력",IF(G13=MIN(G13,Q13,K13,N13,P13),"경기긴장도",IF(P13=MIN(G13,Q13,K13,N13,P13),"자기 통제력","사회적 도움 활용")))),IF(MAX(AK13:AO13)>='판정 기준'!$B$8-'판정 기준'!$B$4,IF(AN13=MAX(AK13:AO13),"실수 후 회복력",IF(AM13=MAX(AK13:AO13),"경기 준비 능력",IF(AK13=MAX(AK13:AO13),"경기긴장도",IF(AO13=MAX(AK13:AO13),"자기 통제력","사회적 도움 활용")))),IF(AN13>0,"실수 후 회복력",IF(AM13>0,"경기 준비 능력",IF(AK13>0,"경기긴장도",IF(AO13>0,"자기 통제력","사회적 도움 활용")))))) -> 실수 후 회복력 | AA13: =INDEX('포지션 정의'!$L$2:$L$9,MATCH(V13,'포지션 정의'!$D$2:$D$9,0)) -> 디디에 드로그바 · 앙투안 그리즈만 · 모하메드 살라 | AB13: =ROUND(100*(1-SQRT(((S13-'포지션 정의'!$N$2)^2+(T13-'포지션 정의'!$O$2)^2+(U13-'포지션 정의'!$P$2)^2)/3)/'판정 기준'!$B$7),0) -> 82 | AC13: =ROUND(100*(1-SQRT(((S13-'포지션 정의'!$N$3)^2+(T13-'포지션 정의'!$O$3)^2+(U13-'포지션 정의'!$P$3)^2)/3)/'판정 기준'!$B$7),0) -> 81 | AD13: =ROUND(100*(1-SQRT(((S13-'포지션 정의'!$N$4)^2+(T13-'포지션 정의'!$O$4)^2+(U13-'포지션 정의'!$P$4)^2)/3)/'판정 기준'!$B$7),0) -> 89 | AE13: =ROUND(100*(1-SQRT(((S13-'포지션 정의'!$N$5)^2+(T13-'포지션 정의'!$O$5)^2+(U13-'포지션 정의'!$P$5)^2)/3)/'판정 기준'!$B$7),0) -> 86 | AF13: =ROUND(100*(1-SQRT(((S13-'포지션 정의'!$N$6)^2+(T13-'포지션 정의'!$O$6)^2+(U13-'포지션 정의'!$P$6)^2)/3)/'판정 기준'!$B$7),0) -> 88 | AG13: =ROUND(100*(1-SQRT(((S13-'포지션 정의'!$N$7)^2+(T13-'포지션 정의'!$O$7)^2+(U13-'포지션 정의'!$P$7)^2)/3)/'판정 기준'!$B$7),0) -> 81 | AH13: =ROUND(100*(1-SQRT(((S13-'포지션 정의'!$N$8)^2+(T13-'포지션 정의'!$O$8)^2+(U13-'포지션 정의'!$P$8)^2)/3)/'판정 기준'!$B$7),0) -> 91 | AI13: =ROUND(100*(1-SQRT(((S13-'포지션 정의'!$N$9)^2+(T13-'포지션 정의'!$O$9)^2+(U13-'포지션 정의'!$P$9)^2)/3)/'판정 기준'!$B$7),0) -> 80 | AJ13: =IF(G13>='판정 기준'!$B$8,"경기긴장도, ","")&IF(Q13>='판정 기준'!$B$8,"사회적 도움 활용, ","")&IF(K13>='판정 기준'!$B$8,"경기 준비 능력, ","")&IF(N13>='판정 기준'!$B$8,"실수 후 회복력, ","")&IF(P13>='판정 기준'!$B$8,"자기 통제력, ","") | AK13: =IF(AND(G13<'판정 기준'!$B$8,OR(AJ13<>"",AP13<>"경기긴장도")),G13,0) -> 0 | AL13: =IF(AND(Q13<'판정 기준'!$B$8,OR(AJ13<>"",AP13<>"사회적 도움 활용")),Q13,0) -> 3.2 | AM13: =IF(AND(K13<'판정 기준'!$B$8,OR(AJ13<>"",AP13<>"경기 준비 능력")),K13,0) -> 3.9 | AN13: =IF(AND(N13<'판정 기준'!$B$8,OR(AJ13<>"",AP13<>"실수 후 회복력")),N13,0) -> 4 | AO13: =IF(AND(P13<'판정 기준'!$B$8,OR(AJ13<>"",AP13<>"자기 통제력")),P13,0) -> 3 | AP13: =IF(Q13=MAX(G13,Q13,K13,N13,P13),"사회적 도움 활용",IF(P13=MAX(G13,Q13,K13,N13,P13),"자기 통제력",IF(G13=MAX(G13,Q13,K13,N13,P13),"경기긴장도",IF(K13=MAX(G13,Q13,K13,N13,P13),"경기 준비 능력","실수 후 회복력")))) -> 경기긴장도
